Workbook
Name ExternalData_1: 详情!$C$14:$C$99
Name ExternalData_1: 业务报告!#REF!
Name ExternalData_2: 业务报告!$A$1:$B$50
Name ExternalData_1: WT报告!$A$1:$B$26
Name ExternalData_1: SP!$A$1:$B$23
Name ExternalData_1: SD!$A$1:$C$33
Name ExternalData_1: SB!#REF!
Name ExternalData_2: SB!$A$1:$C$56
Name ExternalData_1: Base!$A$1:$B$7
Name attributeMapFeedProductType: [1]AttributePTDMAP!$B$1
Name optionalAttributePTDMap: [1]AttributePTDMAP!$A$13:$B$236
Name preferredAttributePTDMap: [1]AttributePTDMAP!$A$237:$B$237

Sheet 详情
A1: 子表-基础数据部分 | B1: 位置 | C1: 名称 | D1: 解释 | E1: 公式
B2: $P$2 | C2: SKU1 | D2: 来自于Base的D2 到 D4 | E2: Base!$D$2:$D$4
B3: $T$2 | C3: SKU2
B4: $X$2 | C4: WOOT
B5: $N5 | C5: 日期
B6: $AC$1 | D6: 综合成本 含头程
B7: $AC$2 | D7: 人民币转美元汇率
B8: $AD$1 | D8: FBA派送费
B9: $AD$2 | D9: 销售佣金率
B10: $AH$2 | E10: 79.99*(1-15%-4%-$AB$2)-$AD$1-$AC$1/$AC$2
B11: $AG$2 | E11: 59.96*(1-5%)-89.99*15%-AC1/AC2
A13: 模块 | B13: 单元格位置 | C13: 名称 | D13: 介绍 | E13: 公式
B14: A5 | C14: 问题 | D14: 满足 业务报告.日期 = 子表.日期 业务报告.MSKU/WOOT ASIN = 子表.SKU1 获取 业务报告.问题/规划 | E14: IFERROR(LOOKUP(1,0/((业务报告!$A:$A=$N5)*(业务报告!$B:$B=$P$2)),业务报告!AU:AU),"")
B15: B5 | C15: 调整 | D15: 满足 业务报告.日期 = 子表.日期 业务报告.MSKU/WOOT ASIN = 子表.SKU1 获取 业务报告.调整 | E15: IFERROR(LOOKUP(1,0/((业务报告!$A:$A=$N5)*(业务报告!$B:$B=$P$2)),业务报告!AV:AV),"")
B16: C5 | C16: 大类排名 | D16: 满足 业务报告.日期 = 子表.日期 业务报告.MSKU/WOOT ASIN = 子表.SKU1 获取 累加 业务报告.大类排名（一般只有一条） | E16: SUMIFS(业务报告!AC:AC,业务报告!$A:$A,$N5,业务报告!$B:$B,$P$2)
B17: D5 | C17: 小类排名 | D17: 满足 业务报告.日期 = 子表.日期 业务报告.MSKU/WOOT ASIN = 子表.SKU1 获取 累加 业务报告.小类排名（一般只有一条） | E17: SUMIFS(业务报告!AD:AD,业务报告!$A:$A,$N5,业务报告!$B:$B,$P$2)
B18: E5 | C18: KW(Laser)自然位 | D18: 满足 业务报告.日期 = 子表.日期 业务报告.MSKU/WOOT ASIN = 子表.SKU1 获取 业务报告.KW(Laser)自然位 | E18: _xlfn.XLOOKUP($N5&$P$2,业务报告!$A:$A&业务报告!$B:$B,业务报告!AE:AE,"")
B19: F5 | C19: 活动 | D19: 满足 业务报告.日期 = 子表.日期 业务报告.MSKU/WOOT ASIN = 子表.SKU1 获取 业务报告.活动 否则为0 | E19: IFERROR(LOOKUP(1,0/((业务报告!$A:$A=$N5)*(业务报告!$B:$B=$P$2)),业务报告!AK:AK),0)
B20: G5 | C20: 划线价/VC LP | D20: 满足 业务报告.日期 = 子表.日期 业务报告.MSKU/WOOT ASIN = 子表.SKU1 获取 累加 业务报告.划线价/VC MSRP（一般只有一条） | E20: SUMIFS(业务报告!AF:AF,业务报告!$A:$A,$N5,业务报告!$B:$B,$P$2)
B21: H5 | C21: 折扣 | D21: 满足 业务报告.日期 = 子表.日期 业务报告.MSKU/WOOT ASIN = 子表.SKU1 获取 业务报告.折扣额/VC-CPN&Promo 否则为0 | E21: IFERROR(LOOKUP(1,0/((业务报告!$A:$A=$N5)*(业务报告!B:B=$P$2)),业务报告!AG:AG),0)
B22: I5 | C22: 成交价 | D22: 满足 业务报告.日期 = 子表.日期 业务报告.MSKU/WOOT ASIN = 子表.SKU1 获取 业务报告.成交价/VC采购价 否则为0 | E22: IFERROR(LOOKUP(1,0/((业务报告!$A:$A=$N5)*(业务报告!$B:$B=$P$2)),业务报告!AH:AH),0)
B23: J5 | C23: WT采购价 | D23: 满足 WT报告.报告日期 = 子表.日期 WT报告.子Asin = 子表.WOOT 获取 累加 WT报告.采购价（一般只有一条） | E23: SUMIFS(WT报告!A:A,WT报告!$C:$C,$N5,WT报告!$H:$H,$X$2)
B24: K5 | C24: 评论星级 | D24: 满足 业务报告.日期 = 子表.日期 业务报告.MSKU/WOOT ASIN = 子表.SKU1 获取 累加 业务报告.评论星级（一般只有一条） | E24: IFERROR(LOOKUP(1,0/((业务报告!$A:$A=$N5)*(业务报告!$B:$B=$P$2)),业务报告!AI:AI),0)
B25: L5 | C25: 新差评 | D25: 满足 业务报告.日期 = 子表.日期 业务报告.MSKU/WOOT ASIN = 子表.SKU1 获取 累加 业务报告.差评（一般只有一条） | E25: IFERROR(LOOKUP(1,0/((业务报告!$A:$A=$N5)*(业务报告!$B:$B=$P$2)),业务报告!AJ:AJ),0)
B26: M5 | C26: 星期 | D26: 星期选择完自动生成 | E26: IFERROR("周"&WEEKDAY(N5,2),"-")
A27: 销售数据 - TM002 | B27: N5 | C27: 日期 | D27: 日期选择完自动生成 | E27: DATE($O$1,$O$2,1)
B28: O5 | C28: 移动 | D28: 满足 业务报告.日期 = 子表.日期 业务报告.MSKU/WOOT ASIN = 子表.SKU1 数据一 累加 业务报告.会话次数 –APP（一般只有一条） 满足 业务报告.日期 = 子表.日期 业务报告.MSKU/WOOT ASIN = 子表.SKU2 数据二 累加 业务报告.会话次数 –APP（一般只有一条） 最后结果 数据一 + 数据二 | E28: SUMIFS(业务报告!G:G,业务报告!$A:$A,$N5,业务报告!$B:$B,$P$2)+SUMIFS(业务报告!G:G,业务报告!$A:$A,$N5,业务报告!$B:$B,$T$2)
B29: P5 | C29: PC | D29: 满足 业务报告.日期 = 子表.日期 业务报告.MSKU/WOOT ASIN = 子表.SKU1 数据一 累加 业务报告.会话次数 – PC（一般只有一条） 满足 业务报告.日期 = 子表.日期 业务报告.MSKU/WOOT ASIN = 子表.SKU2 数据二 累加 业务报告.会话次数 – PC（一般只有一条） 最后结果 数据一 + 数据二 | E29: SUMIFS(业务报告!H:H,业务报告!$A:$A,$N5,业务报告!$B:$B,$P$2)+SUMIFS(业务报告!H:H,业务报告!$A:$A,$N5,业务报告!$B:$B,$T$2)
B30: Q5 | C30: 访客数 | D30: 满足 业务报告.日期 = 子表.日期 业务报告.MSKU/WOOT ASIN = 子表.SKU1 数据一 累加 业务报告.会话次数 – 总计（一般只有一条） 满足 业务报告.日期 = 子表.日期 业务报告.MSKU/WOOT ASIN = 子表.SKU2 数据二 累加 业务报告.会话次数 – 总计（一般只有一条） 最后结果 数据一 + 数据二 | E30: SUMIFS(业务报告!I:I,业务报告!$A:$A,$N5,业务报告!$B:$B,$P$2)+SUMIFS(业务报告!I:I,业务报告!$A:$A,$N5,业务报告!$B:$B,$T$2)
B31: R5 | C31: 销量 | D31: 满足 业务报告.日期 = 子表.日期 业务报告.MSKU/WOOT ASIN = 子表.SKU1 数据一 累加 业务报告.已订购商品数量（一般只有一条） 满足 业务报告.日期 = 子表.日期 业务报告.MSKU/WOOT ASIN = 子表.SKU2 数据二 累加 业务报告.已订购商品数量（一般只有一条） 最后结果 数据一 + 数据二 | E31: SUMIFS(业务报告!T:T,业务报告!$A:$A,$N5,业务报告!$B:$B,$P$2)+SUMIFS(业务报告!T:T,业务报告!$A:$A,$N5,业务报告!$B:$B,$T$2)
B32: S5 | C32: 销量转化率 | D32: (子表.销量 + 子表.WT单量) / 访客数 | E32: IFERROR((R5+V5)/Q5,0)
B33: T5 | C33: 销售额 | D33: 满足 业务报告.日期 = 子表.日期 业务报告.MSKU/WOOT ASIN = 子表.SKU1 数据一 累加 业务报告.已订购商品销售额（一般只有一条） 满足 业务报告.日期 = 子表.日期 业务报告.MSKU/WOOT ASIN = 子表.SKU2 数据二 累加 业务报告.已订购商品销售额（一般只有一条） 最后结果 数据一 + 数据二 | E33: SUMIFS(业务报告!X:X,业务报告!$A:$A,$N5,业务报告!$B:$B,$P$2)+SUMIFS(业务报告!X:X,业务报告!$A:$A,$N5,业务报告!$B:$B,$T$2)
B34: U5 | C34: 测评单量 | D34: 满足 业务报告.日期 = 子表.日期 业务报告.MSKU/WOOT ASIN = 子表.SKU1 数据一 累加 业务报告.主售送测单（一般只有一条） 满足 业务报告.日期 = 子表.日期 业务报告.MSKU/WOOT ASIN = 子表.SKU1 数据二 累加 业务报告.VC送测单（一般只有一条） 最后结果 数据一 + 数据二 | E34: SUMIFS(业务报告!AO:AO,业务报告!$A:$A,$N5,业务报告!$B:$B,$P$2)+SUMIFS(业务报告!AP:AP,业务报告!$A:$A,$N5,业务报告!$B:$B,$P$2)
B35: V5 | C35: WT单量 | D35: 满足 WT报告.报告日期 = 子表.日期 WT报告.子Asin = 子表.WOOT 获取 累加 WT报告.Woot订单数量（一般只有一条） | E35: SUMIFS(WT报告!I:I,WT报告!$C:$C,$N5,WT报告!$H:$H,$X$2)
B36: W5 | C36: WT销售额 | D36: 满足 WT报告.报告日期 = 子表.日期 WT报告.子Asin = 子表.WOOT 获取 累加 WT报告.总销售额（一般只有一条） | E36: SUMIFS(WT报告!Z:Z,WT报告!$C:$C,$N5,WT报告!$H:$H,$X$2)
B37: X5 | C37: 父体单量 | D37: 满足 业务报告.日期 = 子表.日期 业务报告.MSKU/WOOT ASIN = 子表.SKU1 数据一 累加 业务报告.父体单（一般只有一条） 满足 业务报告.日期 = 子表.日期 业务报告.MSKU/WOOT ASIN = 子表.SKU2 数据二 累加 业务报告.父体单（一般只有一条） 最后结果 数据一 + 数据二 + 子表.WT单量 | E37: SUMIFS(业务报告!AS:AS,业务报告!$A:$A,$N5,业务报告!$B:$B,$P$2)+SUMIFS(业务报告!AS:AS,业务报告!$A:$A,$N5,业务报告!$B:$B,$T$2)+V5
A38: 毛利润 | B38: Y5 | C38: 测评费用US$ | D38: 满足 业务报告.日期 = 子表.日期 业务报告.MSKU/WOOT ASIN = 子表.SKU1 数据一 业务报告.主售送测单 * 业务报告*主售测评成本￥/ 汇率 满足 业务报告.日期 = 子表.日期 业务报告.MSKU/WOOT ASIN = 子表.SKU1 数据二 业务报告.VC送测单 * 业务报告*VC测评成本￥/汇率 最后结果 数据一 + 数据二 | E38: SUMIFS(业务报告!AO:AO,业务报告!$A:$A,$N5,业务报告!$B:$B,$P$2)*SUMIFS(业务报告!AM:AM,业务报告!$A:$A,$N5,业务报告!$B:$B,$P$2)/$AC$2+SUMIFS(业务报告!AP:AP,业务报告!$A:$A,$N5,业务报告!$B:$B,$P$2)*SUMIFS(业务报告!AN:AN,业务报告!$A:$A,$N5,业务报告!$B:$B,$P$2)/$AC$2
B39: Z5 | C39: SC广告利润$ | D39: （子表.成交价 *（1 - 子表.销售佣金率 - 4% -10%） - 子表FBA派送费 - 子表.综合成本 含头程/子表.人民币转美元汇率）* 子表.AD单 - 子表.广告费 | E39: (I5*(1-$AD$2-4%-10%)-$AD$1-$AC$1/$AC$2)*BB5-BC5
B40: AA5 | C40: SC利润US$ | D40: 如果 子表.销量 > 子表.WT单量 根据 业务报告.日期 = 子表.日期 业务报告.MSKU/WOOT ASIN = 子表.SKU1 数据一 等于业务报告.主售送测单 否则数据一 = 0 子表.SC广告利润$ * (子表.销量 - 数据一) - 子表.广告费 | E40: (I5*(1-$AD$2-4%-10%)-$AD$1-$AC$1/$AC$2)*(R5-IF(R5>V5,SUMIFS(业务报告!AO:AO,业务报告!$A:$A,$N5,业务报告!$B:$B,$P$2),0))-BC5
B41: AB5 | C41: SC毛利率 | D41: 子表.SC利润$ / (子表.成交价 * 子表.销量) ，出现错误为0 | E41: IFERROR(AA5/(I5*R5),0)
...

Sheet 业务报告
A1: A1 | B1: 日期
A2: B1 | B2: MSKU/WOOT ASIN
A3: C1 | B3: 店铺
A4: D1 | B4: （父）ASIN
A5: E1 | B5: （子）ASIN
A6: F1 | B6: 商品名称
A7: G1 | B7: 会话次数 –APP
A8: H1 | B8: 会话次数 – PC
A9: I1 | B9: 会话次数 – 总计
A10: J1 | B10: 会话百分比 – 移动应用
A11: K1 | B11: 会话百分比 – 浏览器
A12: L1 | B12: 会话百分比 – 总计
... A50: AX1 | B50: None

Sheet WT报告
A1: A2 | B1: 采购价
A2: B2 | B2: 活动价
A3: C2 | B3: 报告日期
A4: D2 | B4: 报告日期
A5: E2 | B5: 星期
A6: F2 | B6: 订单编号
A7: G2 | B7: 产品名称
A8: H2 | B8: 子Asin
A9: I2 | B9: Woot订单数量
A10: J2 | B10: 广告订单数量
A11: K2 | B11: 广告的转化率
A12: L2 | B12: 广告投入产出比
... A26: Z2 | B26: 总销售额

Sheet SP
A1: A1 | B1: 日期
A2: B1 | B2: 广告组合名称
A3: C1 | B3: 货币
A4: D1 | B4: 广告活动名称
A5: E1 | B5: 广告组名称
A6: F1 | B6: Retailer
A7: G1 | B7: 广告SKU/VC-ASIN
A8: H1 | B8: 广告ASIN
A9: I1 | B9: 展示量
A10: J1 | B10: 点击量
A11: K1 | B11: 点击率(CTR)
A12: L1 | B12: 每次点击成本(CPC)
... A23: W1 | B23: 7天内其他SKU销售额

Sheet SD
A1: A1 | B1: 日期
A2: B1 | B2: 广告组合名称
A3: C1 | B3: 货币
A4: D1 | B4: 广告活动名称
A5: E1 | B5: 费用类型
A6: F1 | B6: 广告组名称
A7: G1 | B7: 竞价优化
A8: H1 | B8: 广告SKU
A9: I1 | B9: 广告ASIN
A10: J1 | B10: 展示量
A11: K1 | B11: 可查看的展现量
A12: L1 | B12: 点击量
... A33: AG1 | B33: 14 天内“品牌新客”已售商品数量 (#) -(点击)

Sheet SB
A1: A1 | B1: SKU/ASIN
A2: B1 | B2: 日期
A3: C1 | B3: 广告组合名称
A4: D1 | B4: 货币
A5: E1 | B5: 广告活动名称
A6: F1 | B6: 费用类型
A7: G1 | B7: 国家/地区
A8: H1 | B8: 展示量
A9: I1 | B9: 点击量
A10: J1 | B10: 点击率(CTR)
A11: K1 | B11: 每次点击成本(CPC)
A12: L1 | B12: 花费
... A56: BD1 | B56: Long-Term ROAS

Sheet Base
A1: A1 | B1: 站点
A2: B1 | B2: 店铺
A3: C1 | B3: 型号
A4: D1 | B4: SKU
A5: E1 | B5: ASIN
A6: F1 | B6: 品牌
A7: G1 | B7: 备注

Sheet Sheet7
N1: 年份 | O1: 2025 | P1: SKU1 | T1: SKU2 | X1: WOOT | AB1: 退货 | AC1: 182 | AD1: 5.87 | AE1: SCP0 | AF1: WTP0 | AG1: VCP0 | AH1: 变SCP0 | AI1: 价格 | AJ1: 广告数据汇总 | BH1: 广告明细
N2: 月份 | O2: 9 | P2: ZS-56AI-01ZJ | X2: B0FC6N29Y5 | AB2: 0.08 | AC2: 7.1 | AD2: 0.08 | AE2: =AI2*(1-$AD$2-4%-$AB$2)-$AD$1-$AC$1/$AC$2 -> 32.488197 | AF2: =AI2*60%*(1-4%)-AC1/AC2 -> 20.440437 | AG2: =59.96*(1-5%)-89.99*15%-AC1/AC2 -> 17.829697 | AH2: =79.99*(1-15%-4%-$AB$2)-$AD$1-$AC$1/$AC$2 -> 26.888897 | AI2: 79.99
N3: 销售数据 - TM002 | Y3: 毛利润 | AJ3: WOOT广告数据汇总 | AT3: SC广告数据汇总 | BE3: SP+SBV | BH3: SP广告数据 | BQ3: 展示型广告数据 | BZ3: 品牌视频广告数据
A4: 问题 | B4: 调整 | C4: 大类 排名 | D4: 小类 排名 | E4: KW (Laser)自然位 | F4: 活动 | G4: 划线价/ VC LP | H4: 折扣 | I4: 成交 价 | J4: WT采购价 | K4: 评论 星级 | L4: 新差 评 | M4: 星期 | N4: 日期 | O4: 移动 | P4: PC | Q4: 访客数 | R4: 销量 | S4: 销量 转化率 | T4: 销售额 | U4: 测评 单量 | V4: WT 单量 | W4: WT销售额 | X4: 父体 单量 | Y4: 测评 费用 US$ | Z4: SC 广告 利润$ | AA4: SC 利润 US$ | AB4: SC 毛利 率 | AC4: WT 广告利润$ | AD4: WT 利润 US$ | AE4: SC 变体 利润$ | AF4: VC 变体 利润$ | AG4: 总 利润 US$ | AH4: 总 毛利 率 | AI4: 父体 单个 毛利 | AJ4: 总T ACOS | AK4: 总CPO | AL4: 广告CPA | AM4: 广告 CVR | AN4: CPC | AO4: 广告单 占比 | AP4: 点击 | AQ4: CTR | AR4: AD 单 | AS4: 广告费 | AT4: 总T ACOS | AU4: 总CPO | AV4: 广告CPA | AW4: 广告 CVR | AX4: CPC | AY4: 广告单 占比 | AZ4: 点击 | BA4: CTR | BB4: AD 单 | BC4: 广告费 | BD4: ACoS | BE4: 广告CPA | BF4: 广告 CVR | BG4: AD 单 | BH4: Impressions | BI4: Click | BJ4: CTR | BK4: CPC | BL4: 订单 | BM4: Sales | BN4: CR | BO4: Spend | BP4: ACOS | BQ4: Impressions | BR4: Click | BS4: CTR | BT4: CPC | BU4: 订单 | BV4: Sales | BW4: CR | BX4: Spend | BY4: ACOS | BZ4: Impressions | CA4: Click | CB4: CTR | CC4: CPC | CD4: 订单 | CE4: Sales | CF4: CR | CG4: Spend | CH4: ACOS
A5: {=IFERROR(LOOKUP(1,0/(([2]业务报告!$A:$A=$N5)*([2]业务报告!$B:$B=$P$2)),[2]业务报告!AU:AU),"")} -> 0 | B5: {=IFERROR(LOOKUP(1,0/(([2]业务报告!$A:$A=$N5)*([2]业务报告!$B:$B=$P$2)),[2]业务报告!AV:AV),"")} -> 2.大词词组降低cpc 提高top位比例，广告点击去到top 点击17次，未转化，今晚再观察一晚不做调整，对跑出来不相关词做否定 | C5: =SUMIFS([2]业务报告!AC:AC,[2]业务报告!$A:$A,$N5,[2]业务报告!$B:$B,$P$2) -> 0 | D5: =SUMIFS([2]业务报告!AD:AD,[2]业务报告!$A:$A,$N5,[2]业务报告!$B:$B,$P$2) -> 0 | E5: {=_xlfn.XLOOKUP($N5&$P$2,[2]业务报告!$A:$A&[2]业务报告!$B:$B,[2]业务报告!AE:AE,"")} -> 0 | F5: {=IFERROR(LOOKUP(1,0/(([2]业务报告!$A:$A=$N5)*([2]业务报告!$B:$B=$P$2)),[2]业务报告!AK:AK),0)} -> WBD | G5: =SUMIFS([2]业务报告!AF:AF,[2]业务报告!$A:$A,$N5,[2]业务报告!$B:$B,$P$2) -> 319.89 | H5: {=IFERROR(LOOKUP(1,0/(([2]业务报告!$A:$A=$N5)*([2]业务报告!B:B=$P$2)),[2]业务报告!AG:AG),0)} -> / | I5: {=IFERROR(LOOKUP(1,0/(([2]业务报告!$A:$A=$N5)*([2]业务报告!$B:$B=$P$2)),[2]业务报告!AH:AH),0)} -> 79.99 | J5: =SUMIFS([2]WT报告!A:A,[2]WT报告!$C:$C,$N5,[2]WT报告!$H:$H,$X$2) -> 0 | K5: {=IFERROR(LOOKUP(1,0/(([2]业务报告!$A:$A=$N5)*([2]业务报告!$B:$B=$P$2)),[2]业务报告!AI:AI),0)} -> 0 | L5: {=IFERROR(LOOKUP(1,0/(([2]业务报告!$A:$A=$N5)*([2]业务报告!$B:$B=$P$2)),[2]业务报告!AJ:AJ),0)} -> 0 | M5: =IFERROR("周"&WEEKDAY(N5,2),"-") -> 周1 | N5: =DATE($O$1,$O$2,1) -> 45901 | O5: =SUMIFS([2]业务报告!G:G,[2]业务报告!$A:$A,$N5,[2]业务报告!$B:$B,$P$2)+SUMIFS([2]业务报告!G:G,[2]业务报告!$A:$A,$N5,[2]业务报告!$B:$B,$T$2) -> 0 | P5: =SUMIFS([2]业务报告!H:H,[2]业务报告!$A:$A,$N5,[2]业务报告!$B:$B,$P$2)+SUMIFS([2]业务报告!H:H,[2]业务报告!$A:$A,$N5,[2]业务报告!$B:$B,$T$2) -> 0 | Q5: =SUMIFS([2]业务报告!I:I,[2]业务报告!$A:$A,$N5,[2]业务报告!$B:$B,$P$2)+SUMIFS([2]业务报告!I:I,[2]业务报告!$A:$A,$N5,[2]业务报告!$B:$B,$T$2) -> 0 | R5: =SUMIFS([2]业务报告!T:T,[2]业务报告!$A:$A,$N5,[2]业务报告!$B:$B,$P$2)+SUMIFS([2]业务报告!T:T,[2]业务报告!$A:$A,$N5,[2]业务报告!$B:$B,$T$2) -> 0 | S5: =IFERROR((R5+V5)/Q5,0) -> 0 | T5: =SUMIFS([2]业务报告!X:X,[2]业务报告!$A:$A,$N5,[2]业务报告!$B:$B,$P$2)+SUMIFS([2]业务报告!X:X,[2]业务报告!$A:$A,$N5,[2]业务报告!$B:$B,$T$2) -> 0 | U5: =SUMIFS([2]业务报告!AO:AO,[2]业务报告!$A:$A,$N5,[2]业务报告!$B:$B,$P$2)+SUMIFS([2]业务报告!AP:AP,[2]业务报告!$A:$A,$N5,[2]业务报告!$B:$B,$P$2) -> 0 | V5: =SUMIFS([2]WT报告!I:I,[2]WT报告!$C:$C,$N5,[2]WT报告!$H:$H,$X$2) -> 0 | W5: =SUMIFS([2]WT报告!Z:Z,[2]WT报告!$C:$C,$N5,[2]WT报告!$H:$H,$X$2) -> 0 | X5: =SUMIFS([2]业务报告!AS:AS,[2]业务报告!$A:$A,$N5,[2]业务报告!$B:$B,$P$2)+SUMIFS([2]业务报告!AS:AS,[2]业务报告!$A:$A,$N5,[2]业务报告!$B:$B,$T$2)+V5 -> 0 | Y5: =SUMIFS([2]业务报告!AO:AO,[2]业务报告!$A:$A,$N5,[2]业务报告!$B:$B,$P$2)*SUMIFS([2]业务报告!AM:AM,[2]业务报告!$A:$A,$N5,[2]业务报告!$B:$B,$P$2)/$AC$2+SUMIFS([2]业务报告!AP:AP,[2]业务报告!$A:$A,$N5,[2]业务报告!$B:$B,$P$2)*SUMIFS([2]业务报告!AN:AN,[2]业务报告!$A:$A,$N5,[2]业务报告!$B:$B,$P$2)/$AC$2 -> 0 | Z5: =(I5*(1-$AD$2-4%-10%)-$AD$1-$AC$1/$AC$2)*BB5-BC5 -> 0 | AA5: =(I5*(1-$AD$2-4%-10%)-$AD$1-$AC$1/$AC$2)*(R5-IF(R5>V5,SUMIFS([2]业务报告!AO:AO,[2]业务报告!$A:$A,$N5,[2]业务报告!$B:$B,$P$2),0))-BC5 -> 0 | AB5: =IFERROR(AA5/(I5*R5),0) -> 0 | AC5: =AR5*(J5-$AC$1/$AC$2-J5*4%)-AS5 -> 0 | AD5: =(V5-IF(R5<V5,SUMIFS([2]业务报告!AO:AO,[2]业务报告!$A:$A,$N5,[2]业务报告!$B:$B,$P$2),0))*(J5-$AC$1/$AC$2-J5*4%)-AS5 -> 0 | AE5: {=IFERROR(LOOKUP(1,0/(([2]业务报告!$A:$A=$N5)*([2]业务报告!$B:$B=$P$2)),[2]业务报告!AQ:AQ),0)*$AH$2} -> 0 | AF5: {=IFERROR(LOOKUP(1,0/(([2]业务报告!$A:$A=$N5)*([2]业务报告!$B:$B=$P$2)),[2]业务报告!AR:AR),0)*$AG$2} -> 0 | AG5: =AA5+AD5+AE5+AF5-Y5 -> 0 | AH5: =IFERROR((AG5)/(T5+J5*V5),0) -> 0 | AI5: =IFERROR((AG5)/(X5),0) -> 0 | AJ5: =IFERROR(AS5/(V5*J5),0) -> 0 | AK5: =IFERROR(ROUNDUP(AS5/V5,1),0) -> 0 | AL5: =SUMIFS([2]WT报告!S:S,[2]WT报告!$C:$C,$N5,[2]WT报告!$H:$H,$X$2) -> 0 | AM5: =IFERROR((AR5)/AP5,0) -> 0 | AN5: =SUMIFS([2]WT报告!N:N,[2]WT报告!$C:$C,$N5,[2]WT报告!$H:$H,$X$2) -> 0 | AO5: =IFERROR(AR5/(V5),0) -> 0 | AP5: =SUMIFS([2]WT报告!P:P,[2]WT报告!$C:$C,$N5,[2]WT报告!$H:$H,$X$2) -> 0 | AQ5: =SUMIFS([2]WT报告!Q:Q,[2]WT报告!$C:$C,$N5,[2]WT报告!$H:$H,$X$2) -> 0 | AR5: =SUMIFS([2]WT报告!J:J,[2]WT报告!$C:$C,$N5,[2]WT报告!$H:$H,$X$2) -> 0 | AS5: =SUMIFS([2]WT报告!M:M,[2]WT报告!$C:$C,$N5,[2]WT报告!$H:$H,$X$2) -> 0 | AT5: =IFERROR((BO5+BX5+CG5)/(R5*I5),0) -> 0 | AU5: =IFERROR(ROUNDUP(BC5/R5,1),0) -> 0 | AV5: =IFERROR(ROUNDUP(BC5/BB5,1),0) -> 0 | AW5: =IFERROR((BB5)/AZ5,0) -> 0 | AX5: =IFERROR(BC5/AZ5,0) -> 0 | AY5: =IFERROR((BL5+BU5+CD5)/(R5+V5),0) -> 0 | AZ5: =BI5+BR5+CA5 -> 0 | BA5: =IFERROR((BI5+BR5+CA5)/(BH5+BQ5+BZ5),0) -> 0 | BB5: =BL5+BU5+CD5 -> 0 | BC5: =ROUND(BO5+BX5+CG5,2) -> 0 | BD5: =IFERROR(BC5/(BM5+BV5+CE5),0) -> 0 | BE5: =IFERROR(ROUNDUP((BO5+CG5)/BG5,1),0) -> 0 | BF5: =IFERROR(BG5/(BI5+CA5),0) -> 0 | BG5: =BL5+CD5 -> 0 | BH5: =SUMIFS([2]SP!J:J,[2]SP!A:A,N5,[2]SP!H:H,$P$2)+SUMIFS([2]SP!J:J,[2]SP!A:A,N5,[2]SP!H:H,$T$2) -> 0 | BI5: =SUMIFS([2]SP!K:K,[2]SP!A:A,N5,[2]SP!H:H,$P$2)+SUMIFS([2]SP!K:K,[2]SP!A:A,N5,[2]SP!H:H,$T$2) -> 0 | BJ5: =IFERROR(BI5/BH5,0) -> 0 | BK5: =IFERROR(BO5/BI5,0) -> 0 | BL5: =SUMIFS([2]SP!R:R,[2]SP!A:A,N5,[2]SP!H:H,$P$2)+SUMIFS([2]SP!R:R,[2]SP!A:A,N5,[2]SP!H:H,$T$2) -> 0 | BM5: =SUMIFS([2]SP!O:O,[2]SP!A:A,$N5,[2]SP!H:H,$P$2)+SUMIFS([2]SP!O:O,[2]SP!A:A,$N5,[2]SP!H:H,$T$2) -> 0 | BN5: =IFERROR(BL5/BI5,0) -> 0 | BO5: =SUMIFS([2]SP!N:N,[2]SP!A:A,N5,[2]SP!H:H,$P$2)+SUMIFS([2]SP!N:N,[2]SP!A:A,N5,[2]SP!H:H,$T$2) -> 0 | BP5: =IFERROR(BO5/BM5,0) -> 0 | BQ5: =SUMIFS([2]SD!J:J,[2]SD!A:A,N5,[2]SD!H:H,$P$2)+SUMIFS([2]SD!J:J,[2]SD!A:A,N5,[2]SD!H:H,$T$2) -> 0 | BR5: =SUMIFS([2]SD!L:L,[2]SD!A:A,N5,[2]SD!H:H,$P$2)+SUMIFS([2]SD!L:L,[2]SD!A:A,N5,[2]SD!H:H,$T$2) -> 0 | BS5: =IFERROR(BR5/BQ5,0) -> 0 | BT5: =IFERROR(BX5/BR5,0) -> 0 | BU5: =SUMIFS([2]SD!U:U,[2]SD!A:A,N5,[2]SD!H:H,$P$2)+SUMIFS([2]SD!U:U,[2]SD!A:A,N5,[2]SD!H:H,$T$2) -> 0 | BV5: =SUMIFS([2]SD!V:V,[2]SD!A:A,N5,[2]SD!H:H,$P$2)+SUMIFS([2]SD!V:V,[2]SD!A:A,N5,[2]SD!H:H,$T$2) -> 0 | BW5: =IFERROR(BU5/BR5,0) -> 0 | BX5: =SUMIFS([2]SD!O:O,[2]SD!A:A,N5,[2]SD!H:H,$P$2)+SUMIFS([2]SD!O:O,[2]SD!A:A,N5,[2]SD!H:H,$T$2) -> 0 | BY5: =IFERROR(BX5/BV5,0) -> 0 | BZ5: =SUMIFS([2]SB!H:H,[2]SB!B:B,N5,[2]SB!A:A,$P$2)+SUMIFS([2]SB!H:H,[2]SB!B:B,N5,[2]SB!A:A,$T$2) -> 0 | CA5: =SUMIFS([2]SB!I:I,[2]SB!B:B,N5,[2]SB!A:A,$P$2)+SUMIFS([2]SB!I:I,[2]SB!B:B,N5,[2]SB!A:A,$T$2) -> 0 | CB5: =IFERROR(CA5/BZ5,0) -> 0 | CC5: =IFERROR(CG5/CA5,0) -> 0 | CD5: =SUMIFS([2]SB!Q:Q,[2]SB!B:B,N5,[2]SB!A:A,$P$2)+SUMIFS([2]SB!Q:Q,[2]SB!B:B,N5,[2]SB!A:A,$T$2) -> 0 | CE5: =SUMIFS([2]SB!O:O,[2]SB!B:B,N5,[2]SB!A:A,$P$2)+SUMIFS([2]SB!O:O,[2]SB!B:B,N5,[2]SB!A:A,$T$2) -> 0 | CF5: =IFERROR(CD5/CA5,0) -> 0 | CG5: =SUMIFS([2]SB!L:L,[2]SB!B:B,N5,[2]SB!A:A,$P$2)+SUMIFS([2]SB!L:L,[2]SB!B:B,N5,[2]SB!A:A,$T$2) -> 0 | CH5: =IFERROR(CG5/CE5,0) -> 0
A6: {=IFERROR(LOOKUP(1,0/(([2]业务报告!$A:$A=$N6)*([2]业务报告!$B:$B=$P$2)),[2]业务报告!AU:AU),"")} -> 0 | B6: {=IFERROR(LOOKUP(1,0/(([2]业务报告!$A:$A=$N6)*([2]业务报告!$B:$B=$P$2)),[2]业务报告!AV:AV),"")} -> 0 | C6: =SUMIFS([2]业务报告!AC:AC,[2]业务报告!$A:$A,$N6,[2]业务报告!$B:$B,$P$2) -> 0 | D6: =SUMIFS([2]业务报告!AD:AD,[2]业务报告!$A:$A,$N6,[2]业务报告!$B:$B,$P$2) -> 0 | E6: {=_xlfn.XLOOKUP($N6&$P$2,[2]业务报告!$A:$A&[2]业务报告!$B:$B,[2]业务报告!AE:AE,"")} -> 0 | F6: {=IFERROR(LOOKUP(1,0/(([2]业务报告!$A:$A=$N6)*([2]业务报告!$B:$B=$P$2)),[2]业务报告!AK:AK),0)} -> WBD | G6: =SUMIFS([2]业务报告!AF:AF,[2]业务报告!$A:$A,$N6,[2]业务报告!$B:$B,$P$2) -> 319.89 | H6: {=IFERROR(LOOKUP(1,0/(([2]业务报告!$A:$A=$N6)*([2]业务报告!B:B=$P$2)),[2]业务报告!AG:AG),0)} -> / | I6: {=IFERROR(LOOKUP(1,0/(([2]业务报告!$A:$A=$N6)*([2]业务报告!$B:$B=$P$2)),[2]业务报告!AH:AH),0)} -> 79.99 | J6: =SUMIFS([2]WT报告!A:A,[2]WT报告!$C:$C,$N6,[2]WT报告!$H:$H,$X$2) -> 0 | K6: {=IFERROR(LOOKUP(1,0/(([2]业务报告!$A:$A=$N6)*([2]业务报告!$B:$B=$P$2)),[2]业务报告!AI:AI),0)} -> 0 | L6: {=IFERROR(LOOKUP(1,0/(([2]业务报告!$A:$A=$N6)*([2]业务报告!$B:$B=$P$2)),[2]业务报告!AJ:AJ),0)} -> 0 | M6: =IFERROR("周"&WEEKDAY(N6,2),"-") -> 周2 | N6: =DATE($O$1,$O$2,DAY(N5)+1) -> 45902 | O6: =SUMIFS([2]业务报告!G:G,[2]业务报告!$A:$A,$N6,[2]业务报告!$B:$B,$P$2)+SUMIFS([2]业务报告!G:G,[2]业务报告!$A:$A,$N6,[2]业务报告!$B:$B,$T$2) -> 0 | P6: =SUMIFS([2]业务报告!H:H,[2]业务报告!$A:$A,$N6,[2]业务报告!$B:$B,$P$2)+SUMIFS([2]业务报告!H:H,[2]业务报告!$A:$A,$N6,[2]业务报告!$B:$B,$T$2) -> 0 | Q6: =SUMIFS([2]业务报告!I:I,[2]业务报告!$A:$A,$N6,[2]业务报告!$B:$B,$P$2)+SUMIFS([2]业务报告!I:I,[2]业务报告!$A:$A,$N6,[2]业务报告!$B:$B,$T$2) -> 0 | R6: =SUMIFS([2]业务报告!T:T,[2]业务报告!$A:$A,$N6,[2]业务报告!$B:$B,$P$2)+SUMIFS([2]业务报告!T:T,[2]业务报告!$A:$A,$N6,[2]业务报告!$B:$B,$T$2) -> 0 | S6: =IFERROR((R6+V6)/Q6,0) -> 0 | T6: =SUMIFS([2]业务报告!X:X,[2]业务报告!$A:$A,$N6,[2]业务报告!$B:$B,$P$2)+SUMIFS([2]业务报告!X:X,[2]业务报告!$A:$A,$N6,[2]业务报告!$B:$B,$T$2) -> 0 | U6: =SUMIFS([2]业务报告!AO:AO,[2]业务报告!$A:$A,$N6,[2]业务报告!$B:$B,$P$2)+SUMIFS([2]业务报告!AP:AP,[2]业务报告!$A:$A,$N6,[2]业务报告!$B:$B,$P$2) -> 0 | V6: =SUMIFS([2]WT报告!I:I,[2]WT报告!$C:$C,$N6,[2]WT报告!$H:$H,$X$2) -> 0 | W6: =SUMIFS([2]WT报告!Z:Z,[2]WT报告!$C:$C,$N6,[2]WT报告!$H:$H,$X$2) -> 0 | X6: =SUMIFS([2]业务报告!AS:AS,[2]业务报告!$A:$A,$N6,[2]业务报告!$B:$B,$P$2)+SUMIFS([2]业务报告!AS:AS,[2]业务报告!$A:$A,$N6,[2]业务报告!$B:$B,$T$2)+V6 -> 0 | Y6: =SUMIFS([2]业务报告!AO:AO,[2]业务报告!$A:$A,$N6,[2]业务报告!$B:$B,$P$2)*SUMIFS([2]业务报告!AM:AM,[2]业务报告!$A:$A,$N6,[2]业务报告!$B:$B,$P$2)/$AC$2+SUMIFS([2]业务报告!AP:AP,[2]业务报告!$A:$A,$N6,[2]业务报告!$B:$B,$P$2)*SUMIFS([2]业务报告!AN:AN,[2]业务报告!$A:$A,$N6,[2]业务报告!$B:$B,$P$2)/$AC$2 -> 0 | Z6: =(I6*(1-$AD$2-4%-10%)-$AD$1-$AC$1/$AC$2)*BB6-BC6 -> 0 | AA6: =(I6*(1-$AD$2-4%-10%)-$AD$1-$AC$1/$AC$2)*(R6-IF(R6>V6,SUMIFS([2]业务报告!AO:AO,[2]业务报告!$A:$A,$N6,[2]业务报告!$B:$B,$P$2),0))-BC6 -> 0 | AB6: =IFERROR(AA6/(I6*R6),0) -> 0 | AC6: =AR6*(J6-$AC$1/$AC$2-J6*4%)-AS6 -> 0 | AD6: =(V6-IF(R6<V6,SUMIFS([2]业务报告!AO:AO,[2]业务报告!$A:$A,$N6,[2]业务报告!$B:$B,$P$2),0))*(J6-$AC$1/$AC$2-J6*4%)-AS6 -> 0 | AE6: {=IFERROR(LOOKUP(1,0/(([2]业务报告!$A:$A=$N6)*([2]业务报告!$B:$B=$P$2)),[2]业务报告!AQ:AQ),0)*$AH$2} -> 0 | AF6: {=IFERROR(LOOKUP(1,0/(([2]业务报告!$A:$A=$N6)*([2]业务报告!$B:$B=$P$2)),[2]业务报告!AR:AR),0)*$AG$2} -> 0 | AG6: =AA6+AD6+AE6+AF6-Y6 -> 0 | AH6: =IFERROR((AG6)/(T6+J6*V6),0) -> 0 | AI6: =IFERROR((AG6)/(X6),0) -> 0 | AJ6: =IFERROR(AS6/(V6*J6),0) -> 0 | AK6: =IFERROR(ROUNDUP(AS6/V6,1),0) -> 0 | AL6: =SUMIFS([2]WT报告!S:S,[2]WT报告!$C:$C,$N6,[2]WT报告!$H:$H,$X$2) -> 0 | AM6: =IFERROR((AR6)/AP6,0) -> 0 | AN6: =SUMIFS([2]WT报告!N:N,[2]WT报告!$C:$C,$N6,[2]WT报告!$H:$H,$X$2) -> 0 | AO6: =IFERROR(AR6/(V6),0) -> 0 | AP6: =SUMIFS([2]WT报告!P:P,[2]WT报告!$C:$C,$N6,[2]WT报告!$H:$H,$X$2) -> 0 | AQ6: =SUMIFS([2]WT报告!Q:Q,[2]WT报告!$C:$C,$N6,[2]WT报告!$H:$H,$X$2) -> 0 | AR6: =SUMIFS([2]WT报告!J:J,[2]WT报告!$C:$C,$N6,[2]WT报告!$H:$H,$X$2) -> 0 | AS6: =SUMIFS([2]WT报告!M:M,[2]WT报告!$C:$C,$N6,[2]WT报告!$H:$H,$X$2) -> 0 | AT6: =IFERROR((BO6+BX6+CG6)/(R6*I6),0) -> 0 | AU6: =IFERROR(ROUNDUP(BC6/R6,1),0) -> 0 | AV6: =IFERROR(ROUNDUP(BC6/BB6,1),0) -> 0 | AW6: =IFERROR((BB6)/AZ6,0) -> 0 | AX6: =IFERROR(BC6/AZ6,0) -> 0 | AY6: =IFERROR((BL6+BU6+CD6)/(R6+V6),0) -> 0 | AZ6: =BI6+BR6+CA6 -> 0 | BA6: =IFERROR((BI6+BR6+CA6)/(BH6+BQ6+BZ6),0) -> 0 | BB6: =BL6+BU6+CD6 -> 0 | BC6: =ROUND(BO6+BX6+CG6,2) -> 0 | BD6: =IFERROR(BC6/(BM6+BV6+CE6),0) -> 0 | BE6: =IFERROR(ROUNDUP((BO6+CG6)/BG6,1),0) -> 0 | BF6: =IFERROR(BG6/(BI6+CA6),0) -> 0 | BG6: =BL6+CD6 -> 0 | BH6: =SUMIFS([2]SP!J:J,[2]SP!A:A,N6,[2]SP!H:H,$P$2)+SUMIFS([2]SP!J:J,[2]SP!A:A,N6,[2]SP!H:H,$T$2) -> 0 | BI6: =SUMIFS([2]SP!K:K,[2]SP!A:A,N6,[2]SP!H:H,$P$2)+SUMIFS([2]SP!K:K,[2]SP!A:A,N6,[2]SP!H:H,$T$2) -> 0 | BJ6: =IFERROR(BI6/BH6,0) -> 0 | BK6: =IFERROR(BO6/BI6,0) -> 0 | BL6: =SUMIFS([2]SP!R:R,[2]SP!A:A,N6,[2]SP!H:H,$P$2)+SUMIFS([2]SP!R:R,[2]SP!A:A,N6,[2]SP!H:H,$T$2) -> 0 | BM6: =SUMIFS([2]SP!O:O,[2]SP!A:A,$N6,[2]SP!H:H,$P$2)+SUMIFS([2]SP!O:O,[2]SP!A:A,$N6,[2]SP!H:H,$T$2) -> 0 | BN6: =IFERROR(BL6/BI6,0) -> 0 | BO6: =SUMIFS([2]SP!N:N,[2]SP!A:A,N6,[2]SP!H:H,$P$2)+SUMIFS([2]SP!N:N,[2]SP!A:A,N6,[2]SP!H:H,$T$2) -> 0 | BP6: =IFERROR(BO6/BM6,0) -> 0 | BQ6: =SUMIFS([2]SD!J:J,[2]SD!A:A,N6,[2]SD!H:H,$P$2)+SUMIFS([2]SD!J:J,[2]SD!A:A,N6,[2]SD!H:H,$T$2) -> 0 | BR6: =SUMIFS([2]SD!L:L,[2]SD!A:A,N6,[2]SD!H:H,$P$2)+SUMIFS([2]SD!L:L,[2]SD!A:A,N6,[2]SD!H:H,$T$2) -> 0 | BS6: =IFERROR(BR6/BQ6,0) -> 0 | BT6: =IFERROR(BX6/BR6,0) -> 0 | BU6: =SUMIFS([2]SD!U:U,[2]SD!A:A,N6,[2]SD!H:H,$P$2)+SUMIFS([2]SD!U:U,[2]SD!A:A,N6,[2]SD!H:H,$T$2) -> 0 | BV6: =SUMIFS([2]SD!V:V,[2]SD!A:A,N6,[2]SD!H:H,$P$2)+SUMIFS([2]SD!V:V,[2]SD!A:A,N6,[2]SD!H:H,$T$2) -> 0 | BW6: =IFERROR(BU6/BR6,0) -> 0 | BX6: =SUMIFS([2]SD!O:O,[2]SD!A:A,N6,[2]SD!H:H,$P$2)+SUMIFS([2]SD!O:O,[2]SD!A:A,N6,[2]SD!H:H,$T$2) -> 0 | BY6: =IFERROR(BX6/BV6,0) -> 0 | BZ6: =SUMIFS([2]SB!H:H,[2]SB!B:B,N6,[2]SB!A:A,$P$2)+SUMIFS([2]SB!H:H,[2]SB!B:B,N6,[2]SB!A:A,$T$2) -> 0 | CA6: =SUMIFS([2]SB!I:I,[2]SB!B:B,N6,[2]SB!A:A,$P$2)+SUMIFS([2]SB!I:I,[2]SB!B:B,N6,[2]SB!A:A,$T$2) -> 0 | CB6: =IFERROR(CA6/BZ6,0) -> 0 | CC6: =IFERROR(CG6/CA6,0) -> 0 | CD6: =SUMIFS([2]SB!Q:Q,[2]SB!B:B,N6,[2]SB!A:A,$P$2)+SUMIFS([2]SB!Q:Q,[2]SB!B:B,N6,[2]SB!A:A,$T$2) -> 0 | CE6: =SUMIFS([2]SB!O:O,[2]SB!B:B,N6,[2]SB!A:A,$P$2)+SUMIFS([2]SB!O:O,[2]SB!B:B,N6,[2]SB!A:A,$T$2) -> 0 | CF6: =IFERROR(CD6/CA6,0) -> 0 | CG6: =SUMIFS([2]SB!L:L,[2]SB!B:B,N6,[2]SB!A:A,$P$2)+SUMIFS([2]SB!L:L,[2]SB!B:B,N6,[2]SB!A:A,$T$2) -> 0 | CH6: =IFERROR(CG6/CE6,0) -> 0
A7: {=IFERROR(LOOKUP(1,0/(([2]业务报告!$A:$A=$N7)*([2]业务报告!$B:$B=$P$2)),[2]业务报告!AU:AU),"")} -> 0 | B7: {=IFERROR(LOOKUP(1,0/(([2]业务报告!$A:$A=$N7)*([2]业务报告!$B:$B=$P$2)),[2]业务报告!AV:AV),"")} -> 3.2.3级词词组，cpc提高到2.35 曝光点击偏少，1070曝光只有5次点击，继续提高cpc到2.45 | C7: =SUMIFS([2]业务报告!AC:AC,[2]业务报告!$A:$A,$N7,[2]业务报告!$B:$B,$P$2) -> 0 | D7: =SUMIFS([2]业务报告!AD:AD,[2]业务报告!$A:$A,$N7,[2]业务报告!$B:$B,$P$2) -> 0 | E7: {=_xlfn.XLOOKUP($N7&$P$2,[2]业务报告!$A:$A&[2]业务报告!$B:$B,[2]业务报告!AE:AE,"")} -> 0 | F7: {=IFERROR(LOOKUP(1,0/(([2]业务报告!$A:$A=$N7)*([2]业务报告!$B:$B=$P$2)),[2]业务报告!AK:AK),0)} -> WBD | G7: =SUMIFS([2]业务报告!AF:AF,[2]业务报告!$A:$A,$N7,[2]业务报告!$B:$B,$P$2) -> 319.89 | H7: {=IFERROR(LOOKUP(1,0/(([2]业务报告!$A:$A=$N7)*([2]业务报告!B:B=$P$2)),[2]业务报告!AG:AG),0)} -> / | I7: {=IFERROR(LOOKUP(1,0/(([2]业务报告!$A:$A=$N7)*([2]业务报告!$B:$B=$P$2)),[2]业务报告!AH:AH),0)} -> 79.99 | J7: =SUMIFS([2]WT报告!A:A,[2]WT报告!$C:$C,$N7,[2]WT报告!$H:$H,$X$2) -> 0 | K7: {=IFERROR(LOOKUP(1,0/(([2]业务报告!$A:$A=$N7)*([2]业务报告!$B:$B=$P$2)),[2]业务报告!AI:AI),0)} -> 0 | L7: {=IFERROR(LOOKUP(1,0/(([2]业务报告!$A:$A=$N7)*([2]业务报告!$B:$B=$P$2)),[2]业务报告!AJ:AJ),0)} -> 0 | M7: =IFERROR("周"&WEEKDAY(N7,2),"-") -> 周3 | N7: =DATE($O$1,$O$2,DAY(N6)+1) -> 45903 | O7: =SUMIFS([2]业务报告!G:G,[2]业务报告!$A:$A,$N7,[2]业务报告!$B:$B,$P$2)+SUMIFS([2]业务报告!G:G,[2]业务报告!$A:$A,$N7,[2]业务报告!$B:$B,$T$2) -> 0 | P7: =SUMIFS([2]业务报告!H:H,[2]业务报告!$A:$A,$N7,[2]业务报告!$B:$B,$P$2)+SUMIFS([2]业务报告!H:H,[2]业务报告!$A:$A,$N7,[2]业务报告!$B:$B,$T$2) -> 0 | Q7: =SUMIFS([2]业务报告!I:I,[2]业务报告!$A:$A,$N7,[2]业务报告!$B:$B,$P$2)+SUMIFS([2]业务报告!I:I,[2]业务报告!$A:$A,$N7,[2]业务报告!$B:$B,$T$2) -> 0 | R7: =SUMIFS([2]业务报告!T:T,[2]业务报告!$A:$A,$N7,[2]业务报告!$B:$B,$P$2)+SUMIFS([2]业务报告!T:T,[2]业务报告!$A:$A,$N7,[2]业务报告!$B:$B,$T$2) -> 0 | S7: =IFERROR((R7+V7)/Q7,0) -> 0 | T7: =SUMIFS([2]业务报告!X:X,[2]业务报告!$A:$A,$N7,[2]业务报告!$B:$B,$P$2)+SUMIFS([2]业务报告!X:X,[2]业务报告!$A:$A,$N7,[2]业务报告!$B:$B,$T$2) -> 0 | U7: =SUMIFS([2]业务报告!AO:AO,[2]业务报告!$A:$A,$N7,[2]业务报告!$B:$B,$P$2)+SUMIFS([2]业务报告!AP:AP,[2]业务报告!$A:$A,$N7,[2]业务报告!$B:$B,$P$2) -> 0 | V7: =SUMIFS([2]WT报告!I:I,[2]WT报告!$C:$C,$N7,[2]WT报告!$H:$H,$X$2) -> 0 | W7: =SUMIFS([2]WT报告!Z:Z,[2]WT报告!$C:$C,$N7,[2]WT报告!$H:$H,$X$2) -> 0 | X7: =SUMIFS([2]业务报告!AS:AS,[2]业务报告!$A:$A,$N7,[2]业务报告!$B:$B,$P$2)+SUMIFS([2]业务报告!AS:AS,[2]业务报告!$A:$A,$N7,[2]业务报告!$B:$B,$T$2)+V7 -> 0 | Y7: =SUMIFS([2]业务报告!AO:AO,[2]业务报告!$A:$A,$N7,[2]业务报告!$B:$B,$P$2)*SUMIFS([2]业务报告!AM:AM,[2]业务报告!$A:$A,$N7,[2]业务报告!$B:$B,$P$2)/$AC$2+SUMIFS([2]业务报告!AP:AP,[2]业务报告!$A:$A,$N7,[2]业务报告!$B:$B,$P$2)*SUMIFS([2]业务报告!AN:AN,[2]业务报告!$A:$A,$N7,[2]业务报告!$B:$B,$P$2)/$AC$2 -> 0 | Z7: =(I7*(1-$AD$2-4%-10%)-$AD$1-$AC$1/$AC$2)*BB7-BC7 -> 0 | AA7: =(I7*(1-$AD$2-4%-10%)-$AD$1-$AC$1/$AC$2)*(R7-IF(R7>V7,SUMIFS([2]业务报告!AO:AO,[2]业务报告!$A:$A,$N7,[2]业务报告!$B:$B,$P$2),0))-BC7 -> 0 | AB7: =IFERROR(AA7/(I7*R7),0) -> 0 | AC7: =AR7*(J7-$AC$1/$AC$2-J7*4%)-AS7 -> 0 | AD7: =(V7-IF(R7<V7,SUMIFS([2]业务报告!AO:AO,[2]业务报告!$A:$A,$N7,[2]业务报告!$B:$B,$P$2),0))*(J7-$AC$1/$AC$2-J7*4%)-AS7 -> 0 | AE7: {=IFERROR(LOOKUP(1,0/(([2]业务报告!$A:$A=$N7)*([2]业务报告!$B:$B=$P$2)),[2]业务报告!AQ:AQ),0)*$AH$2} -> 0 | AF7: {=IFERROR(LOOKUP(1,0/(([2]业务报告!$A:$A=$N7)*([2]业务报告!$B:$B=$P$2)),[2]业务报告!AR:AR),0)*$AG$2} -> 0 | AG7: =AA7+AD7+AE7+AF7-Y7 -> 0 | AH7: =IFERROR((AG7)/(T7+J7*V7),0) -> 0 | AI7: =IFERROR((AG7)/(X7),0) -> 0 | AJ7: =IFERROR(AS7/(V7*J7),0) -> 0 | AK7: =IFERROR(ROUNDUP(AS7/V7,1),0) -> 0 | AL7: =SUMIFS([2]WT报告!S:S,[2]WT报告!$C:$C,$N7,[2]WT报告!$H:$H,$X$2) -> 0 | AM7: =IFERROR((AR7)/AP7,0) -> 0 | AN7: =SUMIFS([2]WT报告!N:N,[2]WT报告!$C:$C,$N7,[2]WT报告!$H:$H,$X$2) -> 0 | AO7: =IFERROR(AR7/(V7),0) -> 0 | AP7: =SUMIFS([2]WT报告!P:P,[2]WT报告!$C:$C,$N7,[2]WT报告!$H:$H,$X$2) -> 0 | AQ7: =SUMIFS([2]WT报告!Q:Q,[2]WT报告!$C:$C,$N7,[2]WT报告!$H:$H,$X$2) -> 0 | AR7: =SUMIFS([2]WT报告!J:J,[2]WT报告!$C:$C,$N7,[2]WT报告!$H:$H,$X$2) -> 0 | AS7: =SUMIFS([2]WT报告!M:M,[2]WT报告!$C:$C,$N7,[2]WT报告!$H:$H,$X$2) -> 0 | AT7: =IFERROR((BO7+BX7+CG7)/(R7*I7),0) -> 0 | AU7: =IFERROR(ROUNDUP(BC7/R7,1),0) -> 0 | AV7: =IFERROR(ROUNDUP(BC7/BB7,1),0) -> 0 | AW7: =IFERROR((BB7)/AZ7,0) -> 0 | AX7: =IFERROR(BC7/AZ7,0) -> 0 | AY7: =IFERROR((BL7+BU7+CD7)/(R7+V7),0) -> 0 | AZ7: =BI7+BR7+CA7 -> 0 | BA7: =IFERROR((BI7+BR7+CA7)/(BH7+BQ7+BZ7),0) -> 0 | BB7: =BL7+BU7+CD7 -> 0 | BC7: =ROUND(BO7+BX7+CG7,2) -> 0 | BD7: =IFERROR(BC7/(BM7+BV7+CE7),0) -> 0 | BE7: =IFERROR(ROUNDUP((BO7+CG7)/BG7,1),0) -> 0 | BF7: =IFERROR(BG7/(BI7+CA7),0) -> 0 | BG7: =BL7+CD7 -> 0 | BH7: =SUMIFS([2]SP!J:J,[2]SP!A:A,N7,[2]SP!H:H,$P$2)+SUMIFS([2]SP!J:J,[2]SP!A:A,N7,[2]SP!H:H,$T$2) -> 0 | BI7: =SUMIFS([2]SP!K:K,[2]SP!A:A,N7,[2]SP!H:H,$P$2)+SUMIFS([2]SP!K:K,[2]SP!A:A,N7,[2]SP!H:H,$T$2) -> 0 | BJ7: =IFERROR(BI7/BH7,0) -> 0 | BK7: =IFERROR(BO7/BI7,0) -> 0 | BL7: =SUMIFS([2]SP!R:R,[2]SP!A:A,N7,[2]SP!H:H,$P$2)+SUMIFS([2]SP!R:R,[2]SP!A:A,N7,[2]SP!H:H,$T$2) -> 0 | BM7: =SUMIFS([2]SP!O:O,[2]SP!A:A,$N7,[2]SP!H:H,$P$2)+SUMIFS([2]SP!O:O,[2]SP!A:A,$N7,[2]SP!H:H,$T$2) -> 0 | BN7: =IFERROR(BL7/BI7,0) -> 0 | BO7: =SUMIFS([2]SP!N:N,[2]SP!A:A,N7,[2]SP!H:H,$P$2)+SUMIFS([2]SP!N:N,[2]SP!A:A,N7,[2]SP!H:H,$T$2) -> 0 | BP7: =IFERROR(BO7/BM7,0) -> 0 | BQ7: =SUMIFS([2]SD!J:J,[2]SD!A:A,N7,[2]SD!H:H,$P$2)+SUMIFS([2]SD!J:J,[2]SD!A:A,N7,[2]SD!H:H,$T$2) -> 0 | BR7: =SUMIFS([2]SD!L:L,[2]SD!A:A,N7,[2]SD!H:H,$P$2)+SUMIFS([2]SD!L:L,[2]SD!A:A,N7,[2]SD!H:H,$T$2) -> 0 | BS7: =IFERROR(BR7/BQ7,0) -> 0 | BT7: =IFERROR(BX7/BR7,0) -> 0 | BU7: =SUMIFS([2]SD!U:U,[2]SD!A:A,N7,[2]SD!H:H,$P$2)+SUMIFS([2]SD!U:U,[2]SD!A:A,N7,[2]SD!H:H,$T$2) -> 0 | BV7: =SUMIFS([2]SD!V:V,[2]SD!A:A,N7,[2]SD!H:H,$P$2)+SUMIFS([2]SD!V:V,[2]SD!A:A,N7,[2]SD!H:H,$T$2) -> 0 | BW7: =IFERROR(BU7/BR7,0) -> 0 | BX7: =SUMIFS([2]SD!O:O,[2]SD!A:A,N7,[2]SD!H:H,$P$2)+SUMIFS([2]SD!O:O,[2]SD!A:A,N7,[2]SD!H:H,$T$2) -> 0 | BY7: =IFERROR(BX7/BV7,0) -> 0 | BZ7: =SUMIFS([2]SB!H:H,[2]SB!B:B,N7,[2]SB!A:A,$P$2)+SUMIFS([2]SB!H:H,[2]SB!B:B,N7,[2]SB!A:A,$T$2) -> 0 | CA7: =SUMIFS([2]SB!I:I,[2]SB!B:B,N7,[2]SB!A:A,$P$2)+SUMIFS([2]SB!I:I,[2]SB!B:B,N7,[2]SB!A:A,$T$2) -> 0 | CB7: =IFERROR(CA7/BZ7,0) -> 0 | CC7: =IFERROR(CG7/CA7,0) -> 0 | CD7: =SUMIFS([2]SB!Q:Q,[2]SB!B:B,N7,[2]SB!A:A,$P$2)+SUMIFS([2]SB!Q:Q,[2]SB!B:B,N7,[2]SB!A:A,$T$2) -> 0 | CE7: =SUMIFS([2]SB!O:O,[2]SB!B:B,N7,[2]SB!A:A,$P$2)+SUMIFS([2]SB!O:O,[2]SB!B:B,N7,[2]SB!A:A,$T$2) -> 0 | CF7: =IFERROR(CD7/CA7,0) -> 0 | CG7: =SUMIFS([2]SB!L:L,[2]SB!B:B,N7,[2]SB!A:A,$P$2)+SUMIFS([2]SB!L:L,[2]SB!B:B,N7,[2]SB!A:A,$T$2) -> 0 | CH7: =IFERROR(CG7/CE7,0) -> 0
A8: {=IFERROR(LOOKUP(1,0/(([2]业务报告!$A:$A=$N8)*([2]业务报告!$B:$B=$P$2)),[2]业务报告!AU:AU),"")} -> 0 | B8: {=IFERROR(LOOKUP(1,0/(([2]业务报告!$A:$A=$N8)*([2]业务报告!$B:$B=$P$2)),[2]业务报告!AV:AV),"")} -> 4.2.3级词精准，cpc提高到2.5 ，曝光点击达到预期，无转化，主要预算花在 laser hair removal for women /ipl laser hair removal 各点击10次无转化，继续观察 | C8: =SUMIFS([2]业务报告!AC:AC,[2]业务报告!$A:$A,$N8,[2]业务报告!$B:$B,$P$2) -> 0 | D8: =SUMIFS([2]业务报告!AD:AD,[2]业务报告!$A:$A,$N8,[2]业务报告!$B:$B,$P$2) -> 0 | E8: {=_xlfn.XLOOKUP($N8&$P$2,[2]业务报告!$A:$A&[2]业务报告!$B:$B,[2]业务报告!AE:AE,"")} -> 0 | F8: {=IFERROR(LOOKUP(1,0/(([2]业务报告!$A:$A=$N8)*([2]业务报告!$B:$B=$P$2)),[2]业务报告!AK:AK),0)} -> WBD | G8: =SUMIFS([2]业务报告!AF:AF,[2]业务报告!$A:$A,$N8,[2]业务报告!$B:$B,$P$2) -> 319.89 | H8: {=IFERROR(LOOKUP(1,0/(([2]业务报告!$A:$A=$N8)*([2]业务报告!B:B=$P$2)),[2]业务报告!AG:AG),0)} -> / | I8: {=IFERROR(LOOKUP(1,0/(([2]业务报告!$A:$A=$N8)*([2]业务报告!$B:$B=$P$2)),[2]业务报告!AH:AH),0)} -> 79.99 | J8: =SUMIFS([2]WT报告!A:A,[2]WT报告!$C:$C,$N8,[2]WT报告!$H:$H,$X$2) -> 0 | K8: {=IFERROR(LOOKUP(1,0/(([2]业务报告!$A:$A=$N8)*([2]业务报告!$B:$B=$P$2)),[2]业务报告!AI:AI),0)} -> 0 | L8: {=IFERROR(LOOKUP(1,0/(([2]业务报告!$A:$A=$N8)*([2]业务报告!$B:$B=$P$2)),[2]业务报告!AJ:AJ),0)} -> 0 | M8: =IFERROR("周"&WEEKDAY(N8,2),"-") -> 周4 | N8: =DATE($O$1,$O$2,DAY(N7)+1) -> 45904 | O8: =SUMIFS([2]业务报告!G:G,[2]业务报告!$A:$A,$N8,[2]业务报告!$B:$B,$P$2)+SUMIFS([2]业务报告!G:G,[2]业务报告!$A:$A,$N8,[2]业务报告!$B:$B,$T$2) -> 0 | P8: =SUMIFS([2]业务报告!H:H,[2]业务报告!$A:$A,$N8,[2]业务报告!$B:$B,$P$2)+SUMIFS([2]业务报告!H:H,[2]业务报告!$A:$A,$N8,[2]业务报告!$B:$B,$T$2) -> 0 | Q8: =SUMIFS([2]业务报告!I:I,[2]业务报告!$A:$A,$N8,[2]业务报告!$B:$B,$P$2)+SUMIFS([2]业务报告!I:I,[2]业务报告!$A:$A,$N8,[2]业务报告!$B:$B,$T$2) -> 0 | R8: =SUMIFS([2]业务报告!T:T,[2]业务报告!$A:$A,$N8,[2]业务报告!$B:$B,$P$2)+SUMIFS([2]业务报告!T:T,[2]业务报告!$A:$A,$N8,[2]业务报告!$B:$B,$T$2) -> 0 | S8: =IFERROR((R8+V8)/Q8,0) -> 0 | T8: =SUMIFS([2]业务报告!X:X,[2]业务报告!$A:$A,$N8,[2]业务报告!$B:$B,$P$2)+SUMIFS([2]业务报告!X:X,[2]业务报告!$A:$A,$N8,[2]业务报告!$B:$B,$T$2) -> 0 | U8: =SUMIFS([2]业务报告!AO:AO,[2]业务报告!$A:$A,$N8,[2]业务报告!$B:$B,$P$2)+SUMIFS([2]业务报告!AP:AP,[2]业务报告!$A:$A,$N8,[2]业务报告!$B:$B,$P$2) -> 0 | V8: =SUMIFS([2]WT报告!I:I,[2]WT报告!$C:$C,$N8,[2]WT报告!$H:$H,$X$2) -> 0 | W8: =SUMIFS([2]WT报告!Z:Z,[2]WT报告!$C:$C,$N8,[2]WT报告!$H:$H,$X$2) -> 0 | X8: =SUMIFS([2]业务报告!AS:AS,[2]业务报告!$A:$A,$N8,[2]业务报告!$B:$B,$P$2)+SUMIFS([2]业务报告!AS:AS,[2]业务报告!$A:$A,$N8,[2]业务报告!$B:$B,$T$2)+V8 -> 0 | Y8: =SUMIFS([2]业务报告!AO:AO,[2]业务报告!$A:$A,$N8,[2]业务报告!$B:$B,$P$2)*SUMIFS([2]业务报告!AM:AM,[2]业务报告!$A:$A,$N8,[2]业务报告!$B:$B,$P$2)/$AC$2+SUMIFS([2]业务报告!AP:AP,[2]业务报告!$A:$A,$N8,[2]业务报告!$B:$B,$P$2)*SUMIFS([2]业务报告!AN:AN,[2]业务报告!$A:$A,$N8,[2]业务报告!$B:$B,$P$2)/$AC$2 -> 0 | Z8: =(I8*(1-$AD$2-4%-10%)-$AD$1-$AC$1/$AC$2)*BB8-BC8 -> 0 | AA8: =(I8*(1-$AD$2-4%-10%)-$AD$1-$AC$1/$AC$2)*(R8-IF(R8>V8,SUMIFS([2]业务报告!AO:AO,[2]业务报告!$A:$A,$N8,[2]业务报告!$B:$B,$P$2),0))-BC8 -> 0 | AB8: =IFERROR(AA8/(I8*R8),0) -> 0 | AC8: =AR8*(J8-$AC$1/$AC$2-J8*4%)-AS8 -> 0 | AD8: =(V8-IF(R8<V8,SUMIFS([2]业务报告!AO:AO,[2]业务报告!$A:$A,$N8,[2]业务报告!$B:$B,$P$2),0))*(J8-$AC$1/$AC$2-J8*4%)-AS8 -> 0 | AE8: {=IFERROR(LOOKUP(1,0/(([2]业务报告!$A:$A=$N8)*([2]业务报告!$B:$B=$P$2)),[2]业务报告!AQ:AQ),0)*$AH$2} -> 0 | AF8: {=IFERROR(LOOKUP(1,0/(([2]业务报告!$A:$A=$N8)*([2]业务报告!$B:$B=$P$2)),[2]业务报告!AR:AR),0)*$AG$2} -> 0 | AG8: =AA8+AD8+AE8+AF8-Y8 -> 0 | AH8: =IFERROR((AG8)/(T8+J8*V8),0) -> 0 | AI8: =IFERROR((AG8)/(X8),0) -> 0 | AJ8: =IFERROR(AS8/(V8*J8),0) -> 0 | AK8: =IFERROR(ROUNDUP(AS8/V8,1),0) -> 0 | AL8: =SUMIFS([2]WT报告!S:S,[2]WT报告!$C:$C,$N8,[2]WT报告!$H:$H,$X$2) -> 0 | AM8: =IFERROR((AR8)/AP8,0) -> 0 | AN8: =SUMIFS([2]WT报告!N:N,[2]WT报告!$C:$C,$N8,[2]WT报告!$H:$H,$X$2) -> 0 | AO8: =IFERROR(AR8/(V8),0) -> 0 | AP8: =SUMIFS([2]WT报告!P:P,[2]WT报告!$C:$C,$N8,[2]WT报告!$H:$H,$X$2) -> 0 | AQ8: =SUMIFS([2]WT报告!Q:Q,[2]WT报告!$C:$C,$N8,[2]WT报告!$H:$H,$X$2) -> 0 | AR8: =SUMIFS([2]WT报告!J:J,[2]WT报告!$C:$C,$N8,[2]WT报告!$H:$H,$X$2) -> 0 | AS8: =SUMIFS([2]WT报告!M:M,[2]WT报告!$C:$C,$N8,[2]WT报告!$H:$H,$X$2) -> 0 | AT8: =IFERROR((BO8+BX8+CG8)/(R8*I8),0) -> 0 | AU8: =IFERROR(ROUNDUP(BC8/R8,1),0) -> 0 | AV8: =IFERROR(ROUNDUP(BC8/BB8,1),0) -> 0 | AW8: =IFERROR((BB8)/AZ8,0) -> 0 | AX8: =IFERROR(BC8/AZ8,0) -> 0 | AY8: =IFERROR((BL8+BU8+CD8)/(R8+V8),0) -> 0 | AZ8: =BI8+BR8+CA8 -> 0 | BA8: =IFERROR((BI8+BR8+CA8)/(BH8+BQ8+BZ8),0) -> 0 | BB8: =BL8+BU8+CD8 -> 0 | BC8: =ROUND(BO8+BX8+CG8,2) -> 0 | BD8: =IFERROR(BC8/(BM8+BV8+CE8),0) -> 0 | BE8: =IFERROR(ROUNDUP((BO8+CG8)/BG8,1),0) -> 0 | BF8: =IFERROR(BG8/(BI8+CA8),0) -> 0 | BG8: =BL8+CD8 -> 0 | BH8: =SUMIFS([2]SP!J:J,[2]SP!A:A,N8,[2]SP!H:H,$P$2)+SUMIFS([2]SP!J:J,[2]SP!A:A,N8,[2]SP!H:H,$T$2) -> 0 | BI8: =SUMIFS([2]SP!K:K,[2]SP!A:A,N8,[2]SP!H:H,$P$2)+SUMIFS([2]SP!K:K,[2]SP!A:A,N8,[2]SP!H:H,$T$2) -> 0 | BJ8: =IFERROR(BI8/BH8,0) -> 0 | BK8: =IFERROR(BO8/BI8,0) -> 0 | BL8: =SUMIFS([2]SP!R:R,[2]SP!A:A,N8,[2]SP!H:H,$P$2)+SUMIFS([2]SP!R:R,[2]SP!A:A,N8,[2]SP!H:H,$T$2) -> 0 | BM8: =SUMIFS([2]SP!O:O,[2]SP!A:A,$N8,[2]SP!H:H,$P$2)+SUMIFS([2]SP!O:O,[2]SP!A:A,$N8,[2]SP!H:H,$T$2) -> 0 | BN8: =IFERROR(BL8/BI8,0) -> 0 | BO8: =SUMIFS([2]SP!N:N,[2]SP!A:A,N8,[2]SP!H:H,$P$2)+SUMIFS([2]SP!N:N,[2]SP!A:A,N8,[2]SP!H:H,$T$2) -> 0 | BP8: =IFERROR(BO8/BM8,0) -> 0 | BQ8: =SUMIFS([2]SD!J:J,[2]SD!A:A,N8,[2]SD!H:H,$P$2)+SUMIFS([2]SD!J:J,[2]SD!A:A,N8,[2]SD!H:H,$T$2) -> 0 | BR8: =SUMIFS([2]SD!L:L,[2]SD!A:A,N8,[2]SD!H:H,$P$2)+SUMIFS([2]SD!L:L,[2]SD!A:A,N8,[2]SD!H:H,$T$2) -> 0 | BS8: =IFERROR(BR8/BQ8,0) -> 0 | BT8: =IFERROR(BX8/BR8,0) -> 0 | BU8: =SUMIFS([2]SD!U:U,[2]SD!A:A,N8,[2]SD!H:H,$P$2)+SUMIFS([2]SD!U:U,[2]SD!A:A,N8,[2]SD!H:H,$T$2) -> 0 | BV8: =SUMIFS([2]SD!V:V,[2]SD!A:A,N8,[2]SD!H:H,$P$2)+SUMIFS([2]SD!V:V,[2]SD!A:A,N8,[2]SD!H:H,$T$2) -> 0 | BW8: =IFERROR(BU8/BR8,0) -> 0 | BX8: =SUMIFS([2]SD!O:O,[2]SD!A:A,N8,[2]SD!H:H,$P$2)+SUMIFS([2]SD!O:O,[2]SD!A:A,N8,[2]SD!H:H,$T$2) -> 0 | BY8: =IFERROR(BX8/BV8,0) -> 0 | BZ8: =SUMIFS([2]SB!H:H,[2]SB!B:B,N8,[2]SB!A:A,$P$2)+SUMIFS([2]SB!H:H,[2]SB!B:B,N8,[2]SB!A:A,$T$2) -> 0 | CA8: =SUMIFS([2]SB!I:I,[2]SB!B:B,N8,[2]SB!A:A,$P$2)+SUMIFS([2]SB!I:I,[2]SB!B:B,N8,[2]SB!A:A,$T$2) -> 0 | CB8: =IFERROR(CA8/BZ8,0) -> 0 | CC8: =IFERROR(CG8/CA8,0) -> 0 | CD8: =SUMIFS([2]SB!Q:Q,[2]SB!B:B,N8,[2]SB!A:A,$P$2)+SUMIFS([2]SB!Q:Q,[2]SB!B:B,N8,[2]SB!A:A,$T$2) -> 0 | CE8: =SUMIFS([2]SB!O:O,[2]SB!B:B,N8,[2]SB!A:A,$P$2)+SUMIFS([2]SB!O:O,[2]SB!B:B,N8,[2]SB!A:A,$T$2) -> 0 | CF8: =IFERROR(CD8/CA8,0) -> 0 | CG8: =SUMIFS([2]SB!L:L,[2]SB!B:B,N8,[2]SB!A:A,$P$2)+SUMIFS([2]SB!L:L,[2]SB!B:B,N8,[2]SB!A:A,$T$2) -> 0 | CH8: =IFERROR(CG8/CE8,0) -> 0
A9: {=IFERROR(LOOKUP(1,0/(([2]业务报告!$A:$A=$N9)*([2]业务报告!$B:$B=$P$2)),[2]业务报告!AU:AU),"")} -> 0 | B9: {=IFERROR(LOOKUP(1,0/(([2]业务报告!$A:$A=$N9)*([2]业务报告!$B:$B=$P$2)),[2]业务报告!AV:AV),"")} -> 5.长尾词精准提高竞价到 2美金，只有3次点击，今晚继续提高cpc到2.3 | C9: =SUMIFS([2]业务报告!AC:AC,[2]业务报告!$A:$A,$N9,[2]业务报告!$B:$B,$P$2) -> 0 | D9: =SUMIFS([2]业务报告!AD:AD,[2]业务报告!$A:$A,$N9,[2]业务报告!$B:$B,$P$2) -> 0 | E9: {=_xlfn.XLOOKUP($N9&$P$2,[2]业务报告!$A:$A&[2]业务报告!$B:$B,[2]业务报告!AE:AE,"")} -> 0 | F9: {=IFERROR(LOOKUP(1,0/(([2]业务报告!$A:$A=$N9)*([2]业务报告!$B:$B=$P$2)),[2]业务报告!AK:AK),0)} -> WBD | G9: =SUMIFS([2]业务报告!AF:AF,[2]业务报告!$A:$A,$N9,[2]业务报告!$B:$B,$P$2) -> 319.89 | H9: {=IFERROR(LOOKUP(1,0/(([2]业务报告!$A:$A=$N9)*([2]业务报告!B:B=$P$2)),[2]业务报告!AG:AG),0)} -> / | I9: {=IFERROR(LOOKUP(1,0/(([2]业务报告!$A:$A=$N9)*([2]业务报告!$B:$B=$P$2)),[2]业务报告!AH:AH),0)} -> 79.99 | J9: =SUMIFS([2]WT报告!A:A,[2]WT报告!$C:$C,$N9,[2]WT报告!$H:$H,$X$2) -> 0 | K9: {=IFERROR(LOOKUP(1,0/(([2]业务报告!$A:$A=$N9)*([2]业务报告!$B:$B=$P$2)),[2]业务报告!AI:AI),0)} -> 0 | L9: {=IFERROR(LOOKUP(1,0/(([2]业务报告!$A:$A=$N9)*([2]业务报告!$B:$B=$P$2)),[2]业务报告!AJ:AJ),0)} -> 0 | M9: =IFERROR("周"&WEEKDAY(N9,2),"-") -> 周5 | N9: =DATE($O$1,$O$2,DAY(N8)+1) -> 45905 | O9: =SUMIFS([2]业务报告!G:G,[2]业务报告!$A:$A,$N9,[2]业务报告!$B:$B,$P$2)+SUMIFS([2]业务报告!G:G,[2]业务报告!$A:$A,$N9,[2]业务报告!$B:$B,$T$2) -> 0 | P9: =SUMIFS([2]业务报告!H:H,[2]业务报告!$A:$A,$N9,[2]业务报告!$B:$B,$P$2)+SUMIFS([2]业务报告!H:H,[2]业务报告!$A:$A,$N9,[2]业务报告!$B:$B,$T$2) -> 0 | Q9: =SUMIFS([2]业务报告!I:I,[2]业务报告!$A:$A,$N9,[2]业务报告!$B:$B,$P$2)+SUMIFS([2]业务报告!I:I,[2]业务报告!$A:$A,$N9,[2]业务报告!$B:$B,$T$2) -> 0 | R9: =SUMIFS([2]业务报告!T:T,[2]业务报告!$A:$A,$N9,[2]业务报告!$B:$B,$P$2)+SUMIFS([2]业务报告!T:T,[2]业务报告!$A:$A,$N9,[2]业务报告!$B:$B,$T$2) -> 0 | S9: =IFERROR((R9+V9)/Q9,0) -> 0 | T9: =SUMIFS([2]业务报告!X:X,[2]业务报告!$A:$A,$N9,[2]业务报告!$B:$B,$P$2)+SUMIFS([2]业务报告!X:X,[2]业务报告!$A:$A,$N9,[2]业务报告!$B:$B,$T$2) -> 0 | U9: =SUMIFS([2]业务报告!AO:AO,[2]业务报告!$A:$A,$N9,[2]业务报告!$B:$B,$P$2)+SUMIFS([2]业务报告!AP:AP,[2]业务报告!$A:$A,$N9,[2]业务报告!$B:$B,$P$2) -> 0 | V9: =SUMIFS([2]WT报告!I:I,[2]WT报告!$C:$C,$N9,[2]WT报告!$H:$H,$X$2) -> 0 | W9: =SUMIFS([2]WT报告!Z:Z,[2]WT报告!$C:$C,$N9,[2]WT报告!$H:$H,$X$2) -> 0 | X9: =SUMIFS([2]业务报告!AS:AS,[2]业务报告!$A:$A,$N9,[2]业务报告!$B:$B,$P$2)+SUMIFS([2]业务报告!AS:AS,[2]业务报告!$A:$A,$N9,[2]业务报告!$B:$B,$T$2)+V9 -> 0 | Y9: =SUMIFS([2]业务报告!AO:AO,[2]业务报告!$A:$A,$N9,[2]业务报告!$B:$B,$P$2)*SUMIFS([2]业务报告!AM:AM,[2]业务报告!$A:$A,$N9,[2]业务报告!$B:$B,$P$2)/$AC$2+SUMIFS([2]业务报告!AP:AP,[2]业务报告!$A:$A,$N9,[2]业务报告!$B:$B,$P$2)*SUMIFS([2]业务报告!AN:AN,[2]业务报告!$A:$A,$N9,[2]业务报告!$B:$B,$P$2)/$AC$2 -> 0 | Z9: =(I9*(1-$AD$2-4%-10%)-$AD$1-$AC$1/$AC$2)*BB9-BC9 -> 0 | AA9: =(I9*(1-$AD$2-4%-10%)-$AD$1-$AC$1/$AC$2)*(R9-IF(R9>V9,SUMIFS([2]业务报告!AO:AO,[2]业务报告!$A:$A,$N9,[2]业务报告!$B:$B,$P$2),0))-BC9 -> 0 | AB9: =IFERROR(AA9/(I9*R9),0) -> 0 | AC9: =AR9*(J9-$AC$1/$AC$2-J9*4%)-AS9 -> 0 | AD9: =(V9-IF(R9<V9,SUMIFS([2]业务报告!AO:AO,[2]业务报告!$A:$A,$N9,[2]业务报告!$B:$B,$P$2),0))*(J9-$AC$1/$AC$2-J9*4%)-AS9 -> 0 | AE9: {=IFERROR(LOOKUP(1,0/(([2]业务报告!$A:$A=$N9)*([2]业务报告!$B:$B=$P$2)),[2]业务报告!AQ:AQ),0)*$AH$2} -> 0 | AF9: {=IFERROR(LOOKUP(1,0/(([2]业务报告!$A:$A=$N9)*([2]业务报告!$B:$B=$P$2)),[2]业务报告!AR:AR),0)*$AG$2} -> 0 | AG9: =AA9+AD9+AE9+AF9-Y9 -> 0 | AH9: =IFERROR((AG9)/(T9+J9*V9),0) -> 0 | AI9: =IFERROR((AG9)/(X9),0) -> 0 | AJ9: =IFERROR(AS9/(V9*J9),0) -> 0 | AK9: =IFERROR(ROUNDUP(AS9/V9,1),0) -> 0 | AL9: =SUMIFS([2]WT报告!S:S,[2]WT报告!$C:$C,$N9,[2]WT报告!$H:$H,$X$2) -> 0 | AM9: =IFERROR((AR9)/AP9,0) -> 0 | AN9: =SUMIFS([2]WT报告!N:N,[2]WT报告!$C:$C,$N9,[2]WT报告!$H:$H,$X$2) -> 0 | AO9: =IFERROR(AR9/(V9),0) -> 0 | AP9: =SUMIFS([2]WT报告!P:P,[2]WT报告!$C:$C,$N9,[2]WT报告!$H:$H,$X$2) -> 0 | AQ9: =SUMIFS([2]WT报告!Q:Q,[2]WT报告!$C:$C,$N9,[2]WT报告!$H:$H,$X$2) -> 0 | AR9: =SUMIFS([2]WT报告!J:J,[2]WT报告!$C:$C,$N9,[2]WT报告!$H:$H,$X$2) -> 0 | AS9: =SUMIFS([2]WT报告!M:M,[2]WT报告!$C:$C,$N9,[2]WT报告!$H:$H,$X$2) -> 0 | AT9: =IFERROR((BO9+BX9+CG9)/(R9*I9),0) -> 0 | AU9: =IFERROR(ROUNDUP(BC9/R9,1),0) -> 0 | AV9: =IFERROR(ROUNDUP(BC9/BB9,1),0) -> 0 | AW9: =IFERROR((BB9)/AZ9,0) -> 0 | AX9: =IFERROR(BC9/AZ9,0) -> 0 | AY9: =IFERROR((BL9+BU9+CD9)/(R9+V9),0) -> 0 | AZ9: =BI9+BR9+CA9 -> 0 | BA9: =IFERROR((BI9+BR9+CA9)/(BH9+BQ9+BZ9),0) -> 0 | BB9: =BL9+BU9+CD9 -> 0 | BC9: =ROUND(BO9+BX9+CG9,2) -> 0 | BD9: =IFERROR(BC9/(BM9+BV9+CE9),0) -> 0 | BE9: =IFERROR(ROUNDUP((BO9+CG9)/BG9,1),0) -> 0 | BF9: =IFERROR(BG9/(BI9+CA9),0) -> 0 | BG9: =BL9+CD9 -> 0 | BH9: =SUMIFS([2]SP!J:J,[2]SP!A:A,N9,[2]SP!H:H,$P$2)+SUMIFS([2]SP!J:J,[2]SP!A:A,N9,[2]SP!H:H,$T$2) -> 0 | BI9: =SUMIFS([2]SP!K:K,[2]SP!A:A,N9,[2]SP!H:H,$P$2)+SUMIFS([2]SP!K:K,[2]SP!A:A,N9,[2]SP!H:H,$T$2) -> 0 | BJ9: =IFERROR(BI9/BH9,0) -> 0 | BK9: =IFERROR(BO9/BI9,0) -> 0 | BL9: =SUMIFS([2]SP!R:R,[2]SP!A:A,N9,[2]SP!H:H,$P$2)+SUMIFS([2]SP!R:R,[2]SP!A:A,N9,[2]SP!H:H,$T$2) -> 0 | BM9: =SUMIFS([2]SP!O:O,[2]SP!A:A,$N9,[2]SP!H:H,$P$2)+SUMIFS([2]SP!O:O,[2]SP!A:A,$N9,[2]SP!H:H,$T$2) -> 0 | BN9: =IFERROR(BL9/BI9,0) -> 0 | BO9: =SUMIFS([2]SP!N:N,[2]SP!A:A,N9,[2]SP!H:H,$P$2)+SUMIFS([2]SP!N:N,[2]SP!A:A,N9,[2]SP!H:H,$T$2) -> 0 | BP9: =IFERROR(BO9/BM9,0) -> 0 | BQ9: =SUMIFS([2]SD!J:J,[2]SD!A:A,N9,[2]SD!H:H,$P$2)+SUMIFS([2]SD!J:J,[2]SD!A:A,N9,[2]SD!H:H,$T$2) -> 0 | BR9: =SUMIFS([2]SD!L:L,[2]SD!A:A,N9,[2]SD!H:H,$P$2)+SUMIFS([2]SD!L:L,[2]SD!A:A,N9,[2]SD!H:H,$T$2) -> 0 | BS9: =IFERROR(BR9/BQ9,0) -> 0 | BT9: =IFERROR(BX9/BR9,0) -> 0 | BU9: =SUMIFS([2]SD!U:U,[2]SD!A:A,N9,[2]SD!H:H,$P$2)+SUMIFS([2]SD!U:U,[2]SD!A:A,N9,[2]SD!H:H,$T$2) -> 0 | BV9: =SUMIFS([2]SD!V:V,[2]SD!A:A,N9,[2]SD!H:H,$P$2)+SUMIFS([2]SD!V:V,[2]SD!A:A,N9,[2]SD!H:H,$T$2) -> 0 | BW9: =IFERROR(BU9/BR9,0) -> 0 | BX9: =SUMIFS([2]SD!O:O,[2]SD!A:A,N9,[2]SD!H:H,$P$2)+SUMIFS([2]SD!O:O,[2]SD!A:A,N9,[2]SD!H:H,$T$2) -> 0 | BY9: =IFERROR(BX9/BV9,0) -> 0 | BZ9: =SUMIFS([2]SB!H:H,[2]SB!B:B,N9,[2]SB!A:A,$P$2)+SUMIFS([2]SB!H:H,[2]SB!B:B,N9,[2]SB!A:A,$T$2) -> 0 | CA9: =SUMIFS([2]SB!I:I,[2]SB!B:B,N9,[2]SB!A:A,$P$2)+SUMIFS([2]SB!I:I,[2]SB!B:B,N9,[2]SB!A:A,$T$2) -> 0 | CB9: =IFERROR(CA9/BZ9,0) -> 0 | CC9: =IFERROR(CG9/CA9,0) -> 0 | CD9: =SUMIFS([2]SB!Q:Q,[2]SB!B:B,N9,[2]SB!A:A,$P$2)+SUMIFS([2]SB!Q:Q,[2]SB!B:B,N9,[2]SB!A:A,$T$2) -> 0 | CE9: =SUMIFS([2]SB!O:O,[2]SB!B:B,N9,[2]SB!A:A,$P$2)+SUMIFS([2]SB!O:O,[2]SB!B:B,N9,[2]SB!A:A,$T$2) -> 0 | CF9: =IFERROR(CD9/CA9,0) -> 0 | CG9: =SUMIFS([2]SB!L:L,[2]SB!B:B,N9,[2]SB!A:A,$P$2)+SUMIFS([2]SB!L:L,[2]SB!B:B,N9,[2]SB!A:A,$T$2) -> 0 | CH9: =IFERROR(CG9/CE9,0) -> 0
A10: {=IFERROR(LOOKUP(1,0/(([2]业务报告!$A:$A=$N10)*([2]业务报告!$B:$B=$P$2)),[2]业务报告!AU:AU),"")} -> 0 | B10: {=IFERROR(LOOKUP(1,0/(([2]业务报告!$A:$A=$N10)*([2]业务报告!$B:$B=$P$2)),[2]业务报告!AV:AV),"")} -> 6.长尾词词组 cpc提高到2.35 曝光点击没达到预期，今晚继续提高cpc到2.45 | C10: =SUMIFS([2]业务报告!AC:AC,[2]业务报告!$A:$A,$N10,[2]业务报告!$B:$B,$P$2) -> 0 | D10: =SUMIFS([2]业务报告!AD:AD,[2]业务报告!$A:$A,$N10,[2]业务报告!$B:$B,$P$2) -> 0 | E10: {=_xlfn.XLOOKUP($N10&$P$2,[2]业务报告!$A:$A&[2]业务报告!$B:$B,[2]业务报告!AE:AE,"")} -> 0 | F10: {=IFERROR(LOOKUP(1,0/(([2]业务报告!$A:$A=$N10)*([2]业务报告!$B:$B=$P$2)),[2]业务报告!AK:AK),0)} -> WBD | G10: =SUMIFS([2]业务报告!AF:AF,[2]业务报告!$A:$A,$N10,[2]业务报告!$B:$B,$P$2) -> 319.89 | H10: {=IFERROR(LOOKUP(1,0/(([2]业务报告!$A:$A=$N10)*([2]业务报告!B:B=$P$2)),[2]业务报告!AG:AG),0)} -> / | I10: {=IFERROR(LOOKUP(1,0/(([2]业务报告!$A:$A=$N10)*([2]业务报告!$B:$B=$P$2)),[2]业务报告!AH:AH),0)} -> 79.99 | J10: =SUMIFS([2]WT报告!A:A,[2]WT报告!$C:$C,$N10,[2]WT报告!$H:$H,$X$2) -> 0 | K10: {=IFERROR(LOOKUP(1,0/(([2]业务报告!$A:$A=$N10)*([2]业务报告!$B:$B=$P$2)),[2]业务报告!AI:AI),0)} -> 0 | L10: {=IFERROR(LOOKUP(1,0/(([2]业务报告!$A:$A=$N10)*([2]业务报告!$B:$B=$P$2)),[2]业务报告!AJ:AJ),0)} -> 0 | M10: =IFERROR("周"&WEEKDAY(N10,2),"-") -> 周6 | N10: =DATE($O$1,$O$2,DAY(N9)+1) -> 45906 | O10: =SUMIFS([2]业务报告!G:G,[2]业务报告!$A:$A,$N10,[2]业务报告!$B:$B,$P$2)+SUMIFS([2]业务报告!G:G,[2]业务报告!$A:$A,$N10,[2]业务报告!$B:$B,$T$2) -> 0 | P10: =SUMIFS([2]业务报告!H:H,[2]业务报告!$A:$A,$N10,[2]业务报告!$B:$B,$P$2)+SUMIFS([2]业务报告!H:H,[2]业务报告!$A:$A,$N10,[2]业务报告!$B:$B,$T$2) -> 0 | Q10: =SUMIFS([2]业务报告!I:I,[2]业务报告!$A:$A,$N10,[2]业务报告!$B:$B,$P$2)+SUMIFS([2]业务报告!I:I,[2]业务报告!$A:$A,$N10,[2]业务报告!$B:$B,$T$2) -> 0 | R10: =SUMIFS([2]业务报告!T:T,[2]业务报告!$A:$A,$N10,[2]业务报告!$B:$B,$P$2)+SUMIFS([2]业务报告!T:T,[2]业务报告!$A:$A,$N10,[2]业务报告!$B:$B,$T$2) -> 0 | S10: =IFERROR((R10+V10)/Q10,0) -> 0 | T10: =SUMIFS([2]业务报告!X:X,[2]业务报告!$A:$A,$N10,[2]业务报告!$B:$B,$P$2)+SUMIFS([2]业务报告!X:X,[2]业务报告!$A:$A,$N10,[2]业务报告!$B:$B,$T$2) -> 0 | U10: =SUMIFS([2]业务报告!AO:AO,[2]业务报告!$A:$A,$N10,[2]业务报告!$B:$B,$P$2)+SUMIFS([2]业务报告!AP:AP,[2]业务报告!$A:$A,$N10,[2]业务报告!$B:$B,$P$2) -> 0 | V10: =SUMIFS([2]WT报告!I:I,[2]WT报告!$C:$C,$N10,[2]WT报告!$H:$H,$X$2) -> 0 | W10: =SUMIFS([2]WT报告!Z:Z,[2]WT报告!$C:$C,$N10,[2]WT报告!$H:$H,$X$2) -> 0 | X10: =SUMIFS([2]业务报告!AS:AS,[2]业务报告!$A:$A,$N10,[2]业务报告!$B:$B,$P$2)+SUMIFS([2]业务报告!AS:AS,[2]业务报告!$A:$A,$N10,[2]业务报告!$B:$B,$T$2)+V10 -> 0 | Y10: =SUMIFS([2]业务报告!AO:AO,[2]业务报告!$A:$A,$N10,[2]业务报告!$B:$B,$P$2)*SUMIFS([2]业务报告!AM:AM,[2]业务报告!$A:$A,$N10,[2]业务报告!$B:$B,$P$2)/$AC$2+SUMIFS([2]业务报告!AP:AP,[2]业务报告!$A:$A,$N10,[2]业务报告!$B:$B,$P$2)*SUMIFS([2]业务报告!AN:AN,[2]业务报告!$A:$A,$N10,[2]业务报告!$B:$B,$P$2)/$AC$2 -> 0 | Z10: =(I10*(1-$AD$2-4%-10%)-$AD$1-$AC$1/$AC$2)*BB10-BC10 -> 0 | AA10: =(I10*(1-$AD$2-4%-10%)-$AD$1-$AC$1/$AC$2)*(R10-IF(R10>V10,SUMIFS([2]业务报告!AO:AO,[2]业务报告!$A:$A,$N10,[2]业务报告!$B:$B,$P$2),0))-BC10 -> 0 | AB10: =IFERROR(AA10/(I10*R10),0) -> 0 | AC10: =AR10*(J10-$AC$1/$AC$2-J10*4%)-AS10 -> 0 | AD10: =(V10-IF(R10<V10,SUMIFS([2]业务报告!AO:AO,[2]业务报告!$A:$A,$N10,[2]业务报告!$B:$B,$P$2),0))*(J10-$AC$1/$AC$2-J10*4%)-AS10 -> 0 | AE10: {=IFERROR(LOOKUP(1,0/(([2]业务报告!$A:$A=$N10)*([2]业务报告!$B:$B=$P$2)),[2]业务报告!AQ:AQ),0)*$AH$2} -> 0 | AF10: {=IFERROR(LOOKUP(1,0/(([2]业务报告!$A:$A=$N10)*([2]业务报告!$B:$B=$P$2)),[2]业务报告!AR:AR),0)*$AG$2} -> 0 | AG10: =AA10+AD10+AE10+AF10-Y10 -> 0 | AH10: =IFERROR((AG10)/(T10+J10*V10),0) -> 0 | AI10: =IFERROR((AG10)/(X10),0) -> 0 | AJ10: =IFERROR(AS10/(V10*J10),0) -> 0 | AK10: =IFERROR(ROUNDUP(AS10/V10,1),0) -> 0 | AL10: =SUMIFS([2]WT报告!S:S,[2]WT报告!$C:$C,$N10,[2]WT报告!$H:$H,$X$2) -> 0 | AM10: =IFERROR((AR10)/AP10,0) -> 0 | AN10: =SUMIFS([2]WT报告!N:N,[2]WT报告!$C:$C,$N10,[2]WT报告!$H:$H,$X$2) -> 0 | AO10: =IFERROR(AR10/(V10),0) -> 0 | AP10: =SUMIFS([2]WT报告!P:P,[2]WT报告!$C:$C,$N10,[2]WT报告!$H:$H,$X$2) -> 0 | AQ10: =SUMIFS([2]WT报告!Q:Q,[2]WT报告!$C:$C,$N10,[2]WT报告!$H:$H,$X$2) -> 0 | AR10: =SUMIFS([2]WT报告!J:J,[2]WT报告!$C:$C,$N10,[2]WT报告!$H:$H,$X$2) -> 0 | AS10: =SUMIFS([2]WT报告!M:M,[2]WT报告!$C:$C,$N10,[2]WT报告!$H:$H,$X$2) -> 0 | AT10: =IFERROR((BO10+BX10+CG10)/(R10*I10),0) -> 0 | AU10: =IFERROR(ROUNDUP(BC10/R10,1),0) -> 0 | AV10: =IFERROR(ROUNDUP(BC10/BB10,1),0) -> 0 | AW10: =IFERROR((BB10)/AZ10,0) -> 0 | AX10: =IFERROR(BC10/AZ10,0) -> 0 | AY10: =IFERROR((BL10+BU10+CD10)/(R10+V10),0) -> 0 | AZ10: =BI10+BR10+CA10 -> 0 | BA10: =IFERROR((BI10+BR10+CA10)/(BH10+BQ10+BZ10),0) -> 0 | BB10: =BL10+BU10+CD10 -> 0 | BC10: =ROUND(BO10+BX10+CG10,2) -> 0 | BD10: =IFERROR(BC10/(BM10+BV10+CE10),0) -> 0 | BE10: =IFERROR(ROUNDUP((BO10+CG10)/BG10,1),0) -> 0 | BF10: =IFERROR(BG10/(BI10+CA10),0) -> 0 | BG10: =BL10+CD10 -> 0 | BH10: =SUMIFS([2]SP!J:J,[2]SP!A:A,N10,[2]SP!H:H,$P$2)+SUMIFS([2]SP!J:J,[2]SP!A:A,N10,[2]SP!H:H,$T$2) -> 0 | BI10: =SUMIFS([2]SP!K:K,[2]SP!A:A,N10,[2]SP!H:H,$P$2)+SUMIFS([2]SP!K:K,[2]SP!A:A,N10,[2]SP!H:H,$T$2) -> 0 | BJ10: =IFERROR(BI10/BH10,0) -> 0 | BK10: =IFERROR(BO10/BI10,0) -> 0 | BL10: =SUMIFS([2]SP!R:R,[2]SP!A:A,N10,[2]SP!H:H,$P$2)+SUMIFS([2]SP!R:R,[2]SP!A:A,N10,[2]SP!H:H,$T$2) -> 0 | BM10: =SUMIFS([2]SP!O:O,[2]SP!A:A,$N10,[2]SP!H:H,$P$2)+SUMIFS([2]SP!O:O,[2]SP!A:A,$N10,[2]SP!H:H,$T$2) -> 0 | BN10: =IFERROR(BL10/BI10,0) -> 0 | BO10: =SUMIFS([2]SP!N:N,[2]SP!A:A,N10,[2]SP!H:H,$P$2)+SUMIFS([2]SP!N:N,[2]SP!A:A,N10,[2]SP!H:H,$T$2) -> 0 | BP10: =IFERROR(BO10/BM10,0) -> 0 | BQ10: =SUMIFS([2]SD!J:J,[2]SD!A:A,N10,[2]SD!H:H,$P$2)+SUMIFS([2]SD!J:J,[2]SD!A:A,N10,[2]SD!H:H,$T$2) -> 0 | BR10: =SUMIFS([2]SD!L:L,[2]SD!A:A,N10,[2]SD!H:H,$P$2)+SUMIFS([2]SD!L:L,[2]SD!A:A,N10,[2]SD!H:H,$T$2) -> 0 | BS10: =IFERROR(BR10/BQ10,0) -> 0 | BT10: =IFERROR(BX10/BR10,0) -> 0 | BU10: =SUMIFS([2]SD!U:U,[2]SD!A:A,N10,[2]SD!H:H,$P$2)+SUMIFS([2]SD!U:U,[2]SD!A:A,N10,[2]SD!H:H,$T$2) -> 0 | BV10: =SUMIFS([2]SD!V:V,[2]SD!A:A,N10,[2]SD!H:H,$P$2)+SUMIFS([2]SD!V:V,[2]SD!A:A,N10,[2]SD!H:H,$T$2) -> 0 | BW10: =IFERROR(BU10/BR10,0) -> 0 | BX10: =SUMIFS([2]SD!O:O,[2]SD!A:A,N10,[2]SD!H:H,$P$2)+SUMIFS([2]SD!O:O,[2]SD!A:A,N10,[2]SD!H:H,$T$2) -> 0 | BY10: =IFERROR(BX10/BV10,0) -> 0 | BZ10: =SUMIFS([2]SB!H:H,[2]SB!B:B,N10,[2]SB!A:A,$P$2)+SUMIFS([2]SB!H:H,[2]SB!B:B,N10,[2]SB!A:A,$T$2) -> 0 | CA10: =SUMIFS([2]SB!I:I,[2]SB!B:B,N10,[2]SB!A:A,$P$2)+SUMIFS([2]SB!I:I,[2]SB!B:B,N10,[2]SB!A:A,$T$2) -> 0 | CB10: =IFERROR(CA10/BZ10,0) -> 0 | CC10: =IFERROR(CG10/CA10,0) -> 0 | CD10: =SUMIFS([2]SB!Q:Q,[2]SB!B:B,N10,[2]SB!A:A,$P$2)+SUMIFS([2]SB!Q:Q,[2]SB!B:B,N10,[2]SB!A:A,$T$2) -> 0 | CE10: =SUMIFS([2]SB!O:O,[2]SB!B:B,N10,[2]SB!A:A,$P$2)+SUMIFS([2]SB!O:O,[2]SB!B:B,N10,[2]SB!A:A,$T$2) -> 0 | CF10: =IFERROR(CD10/CA10,0) -> 0 | CG10: =SUMIFS([2]SB!L:L,[2]SB!B:B,N10,[2]SB!A:A,$P$2)+SUMIFS([2]SB!L:L,[2]SB!B:B,N10,[2]SB!A:A,$T$2) -> 0 | CH10: =IFERROR(CG10/CE10,0) -> 0
A11: {=IFERROR(LOOKUP(1,0/(([2]业务报告!$A:$A=$N11)*([2]业务报告!$B:$B=$P$2)),[2]业务报告!AU:AU),"")} -> 0 | B11: {=IFERROR(LOOKUP(1,0/(([2]业务报告!$A:$A=$N11)*([2]业务报告!$B:$B=$P$2)),[2]业务报告!AV:AV),"")} -> 0 | C11: =SUMIFS([2]业务报告!AC:AC,[2]业务报告!$A:$A,$N11,[2]业务报告!$B:$B,$P$2) -> 0 | D11: =SUMIFS([2]业务报告!AD:AD,[2]业务报告!$A:$A,$N11,[2]业务报告!$B:$B,$P$2) -> 0 | E11: {=_xlfn.XLOOKUP($N11&$P$2,[2]业务报告!$A:$A&[2]业务报告!$B:$B,[2]业务报告!AE:AE,"")} -> 0 | F11: {=IFERROR(LOOKUP(1,0/(([2]业务报告!$A:$A=$N11)*([2]业务报告!$B:$B=$P$2)),[2]业务报告!AK:AK),0)} -> WBD | G11: =SUMIFS([2]业务报告!AF:AF,[2]业务报告!$A:$A,$N11,[2]业务报告!$B:$B,$P$2) -> 319.89 | H11: {=IFERROR(LOOKUP(1,0/(([2]业务报告!$A:$A=$N11)*([2]业务报告!B:B=$P$2)),[2]业务报告!AG:AG),0)} -> / | I11: {=IFERROR(LOOKUP(1,0/(([2]业务报告!$A:$A=$N11)*([2]业务报告!$B:$B=$P$2)),[2]业务报告!AH:AH),0)} -> 79.99 | J11: =SUMIFS([2]WT报告!A:A,[2]WT报告!$C:$C,$N11,[2]WT报告!$H:$H,$X$2) -> 0 | K11: {=IFERROR(LOOKUP(1,0/(([2]业务报告!$A:$A=$N11)*([2]业务报告!$B:$B=$P$2)),[2]业务报告!AI:AI),0)} -> 0 | L11: {=IFERROR(LOOKUP(1,0/(([2]业务报告!$A:$A=$N11)*([2]业务报告!$B:$B=$P$2)),[2]业务报告!AJ:AJ),0)} -> 0 | M11: =IFERROR("周"&WEEKDAY(N11,2),"-") -> 周7 | N11: =DATE($O$1,$O$2,DAY(N10)+1) -> 45907 | O11: =SUMIFS([2]业务报告!G:G,[2]业务报告!$A:$A,$N11,[2]业务报告!$B:$B,$P$2)+SUMIFS([2]业务报告!G:G,[2]业务报告!$A:$A,$N11,[2]业务报告!$B:$B,$T$2) -> 0 | P11: =SUMIFS([2]业务报告!H:H,[2]业务报告!$A:$A,$N11,[2]业务报告!$B:$B,$P$2)+SUMIFS([2]业务报告!H:H,[2]业务报告!$A:$A,$N11,[2]业务报告!$B:$B,$T$2) -> 0 | Q11: =SUMIFS([2]业务报告!I:I,[2]业务报告!$A:$A,$N11,[2]业务报告!$B:$B,$P$2)+SUMIFS([2]业务报告!I:I,[2]业务报告!$A:$A,$N11,[2]业务报告!$B:$B,$T$2) -> 0 | R11: =SUMIFS([2]业务报告!T:T,[2]业务报告!$A:$A,$N11,[2]业务报告!$B:$B,$P$2)+SUMIFS([2]业务报告!T:T,[2]业务报告!$A:$A,$N11,[2]业务报告!$B:$B,$T$2) -> 0 | S11: =IFERROR((R11+V11)/Q11,0) -> 0 | T11: =SUMIFS([2]业务报告!X:X,[2]业务报告!$A:$A,$N11,[2]业务报告!$B:$B,$P$2)+SUMIFS([2]业务报告!X:X,[2]业务报告!$A:$A,$N11,[2]业务报告!$B:$B,$T$2) -> 0 | U11: =SUMIFS([2]业务报告!AO:AO,[2]业务报告!$A:$A,$N11,[2]业务报告!$B:$B,$P$2)+SUMIFS([2]业务报告!AP:AP,[2]业务报告!$A:$A,$N11,[2]业务报告!$B:$B,$P$2) -> 0 | V11: =SUMIFS([2]WT报告!I:I,[2]WT报告!$C:$C,$N11,[2]WT报告!$H:$H,$X$2) -> 0 | W11: =SUMIFS([2]WT报告!Z:Z,[2]WT报告!$C:$C,$N11,[2]WT报告!$H:$H,$X$2) -> 0 | X11: =SUMIFS([2]业务报告!AS:AS,[2]业务报告!$A:$A,$N11,[2]业务报告!$B:$B,$P$2)+SUMIFS([2]业务报告!AS:AS,[2]业务报告!$A:$A,$N11,[2]业务报告!$B:$B,$T$2)+V11 -> 0 | Y11: =SUMIFS([2]业务报告!AO:AO,[2]业务报告!$A:$A,$N11,[2]业务报告!$B:$B,$P$2)*SUMIFS([2]业务报告!AM:AM,[2]业务报告!$A:$A,$N11,[2]业务报告!$B:$B,$P$2)/$AC$2+SUMIFS([2]业务报告!AP:AP,[2]业务报告!$A:$A,$N11,[2]业务报告!$B:$B,$P$2)*SUMIFS([2]业务报告!AN:AN,[2]业务报告!$A:$A,$N11,[2]业务报告!$B:$B,$P$2)/$AC$2 -> 0 | Z11: =(I11*(1-$AD$2-4%-10%)-$AD$1-$AC$1/$AC$2)*BB11-BC11 -> 0 | AA11: =(I11*(1-$AD$2-4%-10%)-$AD$1-$AC$1/$AC$2)*(R11-IF(R11>V11,SUMIFS([2]业务报告!AO:AO,[2]业务报告!$A:$A,$N11,[2]业务报告!$B:$B,$P$2),0))-BC11 -> 0 | AB11: =IFERROR(AA11/(I11*R11),0) -> 0 | AC11: =AR11*(J11-$AC$1/$AC$2-J11*4%)-AS11 -> 0 | AD11: =(V11-IF(R11<V11,SUMIFS([2]业务报告!AO:AO,[2]业务报告!$A:$A,$N11,[2]业务报告!$B:$B,$P$2),0))*(J11-$AC$1/$AC$2-J11*4%)-AS11 -> 0 | AE11: {=IFERROR(LOOKUP(1,0/(([2]业务报告!$A:$A=$N11)*([2]业务报告!$B:$B=$P$2)),[2]业务报告!AQ:AQ),0)*$AH$2} -> 0 | AF11: {=IFERROR(LOOKUP(1,0/(([2]业务报告!$A:$A=$N11)*([2]业务报告!$B:$B=$P$2)),[2]业务报告!AR:AR),0)*$AG$2} -> 0 | AG11: =AA11+AD11+AE11+AF11-Y11 -> 0 | AH11: =IFERROR((AG11)/(T11+J11*V11),0) -> 0 | AI11: =IFERROR((AG11)/(X11),0) -> 0 | AJ11: =IFERROR(AS11/(V11*J11),0) -> 0 | AK11: =IFERROR(ROUNDUP(AS11/V11,1),0) -> 0 | AL11: =SUMIFS([2]WT报告!S:S,[2]WT报告!$C:$C,$N11,[2]WT报告!$H:$H,$X$2) -> 0 | AM11: =IFERROR((AR11)/AP11,0) -> 0 | AN11: =SUMIFS([2]WT报告!N:N,[2]WT报告!$C:$C,$N11,[2]WT报告!$H:$H,$X$2) -> 0 | AO11: =IFERROR(AR11/(V11),0) -> 0 | AP11: =SUMIFS([2]WT报告!P:P,[2]WT报告!$C:$C,$N11,[2]WT报告!$H:$H,$X$2) -> 0 | AQ11: =SUMIFS([2]WT报告!Q:Q,[2]WT报告!$C:$C,$N11,[2]WT报告!$H:$H,$X$2) -> 0 | AR11: =SUMIFS([2]WT报告!J:J,[2]WT报告!$C:$C,$N11,[2]WT报告!$H:$H,$X$2) -> 0 | AS11: =SUMIFS([2]WT报告!M:M,[2]WT报告!$C:$C,$N11,[2]WT报告!$H:$H,$X$2) -> 0 | AT11: =IFERROR((BO11+BX11+CG11)/(R11*I11),0) -> 0 | AU11: =IFERROR(ROUNDUP(BC11/R11,1),0) -> 0 | AV11: =IFERROR(ROUNDUP(BC11/BB11,1),0) -> 0 | AW11: =IFERROR((BB11)/AZ11,0) -> 0 | AX11: =IFERROR(BC11/AZ11,0) -> 0 | AY11: =IFERROR((BL11+BU11+CD11)/(R11+V11),0) -> 0 | AZ11: =BI11+BR11+CA11 -> 0 | BA11: =IFERROR((BI11+BR11+CA11)/(BH11+BQ11+BZ11),0) -> 0 | BB11: =BL11+BU11+CD11 -> 0 | BC11: =ROUND(BO11+BX11+CG11,2) -> 0 | BD11: =IFERROR(BC11/(BM11+BV11+CE11),0) -> 0 | BE11: =IFERROR(ROUNDUP((BO11+CG11)/BG11,1),0) -> 0 | BF11: =IFERROR(BG11/(BI11+CA11),0) -> 0 | BG11: =BL11+CD11 -> 0 | BH11: =SUMIFS([2]SP!J:J,[2]SP!A:A,N11,[2]SP!H:H,$P$2)+SUMIFS([2]SP!J:J,[2]SP!A:A,N11,[2]SP!H:H,$T$2) -> 0 | BI11: =SUMIFS([2]SP!K:K,[2]SP!A:A,N11,[2]SP!H:H,$P$2)+SUMIFS([2]SP!K:K,[2]SP!A:A,N11,[2]SP!H:H,$T$2) -> 0 | BJ11: =IFERROR(BI11/BH11,0) -> 0 | BK11: =IFERROR(BO11/BI11,0) -> 0 | BL11: =SUMIFS([2]SP!R:R,[2]SP!A:A,N11,[2]SP!H:H,$P$2)+SUMIFS([2]SP!R:R,[2]SP!A:A,N11,[2]SP!H:H,$T$2) -> 0 | BM11: =SUMIFS([2]SP!O:O,[2]SP!A:A,$N11,[2]SP!H:H,$P$2)+SUMIFS([2]SP!O:O,[2]SP!A:A,$N11,[2]SP!H:H,$T$2) -> 0 | BN11: =IFERROR(BL11/BI11,0) -> 0 | BO11: =SUMIFS([2]SP!N:N,[2]SP!A:A,N11,[2]SP!H:H,$P$2)+SUMIFS([2]SP!N:N,[2]SP!A:A,N11,[2]SP!H:H,$T$2) -> 0 | BP11: =IFERROR(BO11/BM11,0) -> 0 | BQ11: =SUMIFS([2]SD!J:J,[2]SD!A:A,N11,[2]SD!H:H,$P$2)+SUMIFS([2]SD!J:J,[2]SD!A:A,N11,[2]SD!H:H,$T$2) -> 0 | BR11: =SUMIFS([2]SD!L:L,[2]SD!A:A,N11,[2]SD!H:H,$P$2)+SUMIFS([2]SD!L:L,[2]SD!A:A,N11,[2]SD!H:H,$T$2) -> 0 | BS11: =IFERROR(BR11/BQ11,0) -> 0 | BT11: =IFERROR(BX11/BR11,0) -> 0 | BU11: =SUMIFS([2]SD!U:U,[2]SD!A:A,N11,[2]SD!H:H,$P$2)+SUMIFS([2]SD!U:U,[2]SD!A:A,N11,[2]SD!H:H,$T$2) -> 0 | BV11: =SUMIFS([2]SD!V:V,[2]SD!A:A,N11,[2]SD!H:H,$P$2)+SUMIFS([2]SD!V:V,[2]SD!A:A,N11,[2]SD!H:H,$T$2) -> 0 | BW11: =IFERROR(BU11/BR11,0) -> 0 | BX11: =SUMIFS([2]SD!O:O,[2]SD!A:A,N11,[2]SD!H:H,$P$2)+SUMIFS([2]SD!O:O,[2]SD!A:A,N11,[2]SD!H:H,$T$2) -> 0 | BY11: =IFERROR(BX11/BV11,0) -> 0 | BZ11: =SUMIFS([2]SB!H:H,[2]SB!B:B,N11,[2]SB!A:A,$P$2)+SUMIFS([2]SB!H:H,[2]SB!B:B,N11,[2]SB!A:A,$T$2) -> 0 | CA11: =SUMIFS([2]SB!I:I,[2]SB!B:B,N11,[2]SB!A:A,$P$2)+SUMIFS([2]SB!I:I,[2]SB!B:B,N11,[2]SB!A:A,$T$2) -> 0 | CB11: =IFERROR(CA11/BZ11,0) -> 0 | CC11: =IFERROR(CG11/CA11,0) -> 0 | CD11: =SUMIFS([2]SB!Q:Q,[2]SB!B:B,N11,[2]SB!A:A,$P$2)+SUMIFS([2]SB!Q:Q,[2]SB!B:B,N11,[2]SB!A:A,$T$2) -> 0 | CE11: =SUMIFS([2]SB!O:O,[2]SB!B:B,N11,[2]SB!A:A,$P$2)+SUMIFS([2]SB!O:O,[2]SB!B:B,N11,[2]SB!A:A,$T$2) -> 0 | CF11: =IFERROR(CD11/CA11,0) -> 0 | CG11: =SUMIFS([2]SB!L:L,[2]SB!B:B,N11,[2]SB!A:A,$P$2)+SUMIFS([2]SB!L:L,[2]SB!B:B,N11,[2]SB!A:A,$T$2) -> 0 | CH11: =IFERROR(CG11/CE11,0) -> 0
